Workbook

Sheet PDCA Main Page
A1: PDCA Chart 05.02.2026
A2: Problem
B3: Missing milestones & timeliness
A4: Scope
A5: SF
A6: Lane
G7: Nov '25 | H7: Dec '25 | I7: Jan '26 | J7: Feb '26 F | K7: Mar '26 F | L7: Apr '26 F | M7: May '26 F | N7: Jun '26 F | O7: Jul '26 F | P7: Aug '26 F | Q7: Sep '26 F | R7: Oct '26 F | S7: YTD
A8: Responsible | D8: Completeness (Critical) | G8: 0.82 | H8: 0.84 | I8: 0.861
D9: Timeliness (Critical) | G9: 0.1 | H9: 0.22 | I9: 0.487
B10: Maersk MOF execution | D10: Completeness (All) | G10: N/A | H10: N/A | I10: 0.73
D11: Timeliness (All) | G11: N/A | H11: N/A | I11: 0.46
D12: ETA accuracy 2P
D13: ETA Accuracy 2D
D14: SC Reference Completeness (CIV or DN) | G14: N/A | H14: N/A | I14: 0.8
D15: Target | G15: 0.95 | H15: 0.95 | I15: 0.95 | J15: 0.95 | K15: 0.95 | L15: 0.95 | M15: 0.95 | N15: 0.95 | O15: 0.95 | P15: 0.95 | Q15: 0.95 | R15: 0.95
D16: Timeliness Target (Apr) | L16: 0.7 | M16: 0.95 | N16: 0.95 | O16: 0.95 | P16: 0.95 | Q16: 0.95 | R16: 0.95
A17: Nr | B17: Main Problems | C17: Product Impact | D17: Category | G17: W01 | H17: W02 | I17: W03 | J17: W04 | K17: W05 | L17: W06 | M17: W07 | N17: W08 | O17: W09 | P17: W10 | Q17: W11 | R17: W12 | S17: YTD
A18: 1 | B18: SC4 – S00 - Shipment created (Actual) | C18: high | D18: Completeness (Critical) | G18: ='SC4 Data'!F5 -> 0.52 | H18: ='SC4 Data'!K5 -> 0.36 | I18: ='SC4 Data'!P5 -> 0.35 | J18: ='SC4 Data'!U5 -> 0.5 | K18: ='SC4 Data'!Z5 -> 0.55218216 | L18: ='SC4 Data'!AE5 -> 0.61 | M18: ='SC4 Data'!AJ5 -> 0
A19: 2 | B19: SC4 – S00 - Shipment created (Actual) | C19: high | D19: Timeliness (Critical) | G19: ='SC4 Data'!G5 -> 0.52 | H19: ='SC4 Data'!L5 -> 0.36 | I19: ='SC4 Data'!Q5 -> 0.35 | J19: ='SC4 Data'!V5 -> 0.49 | K19: ='SC4 Data'!AA5 -> 0.54648956 | L19: ='SC4 Data'!AF5 -> 0.6 | M19: ='SC4 Data'!AK5 -> 0
A20: 3 | B20: SC4 – S02 - Collected (Estimated) | C20: high | D20: Completeness (Critical) | G20: ='SC4 Data'!F6 -> 0.79 | H20: ='SC4 Data'!K6 -> 0.83 | I20: ='SC4 Data'!P6 -> 0.85 | J20: ='SC4 Data'!U6 -> 0.87 | K20: ='SC4 Data'!Z6 -> 0.84673367 | L20: ='SC4 Data'!AE6 -> 0.9 | M20: ='SC4 Data'!AJ6 -> 0
A21: 4 | B21: SC4 – S02 - Collected (Estimated) | C21: high | D21: Timeliness (Critical) | G21: ='SC4 Data'!G6 -> 0.41 | H21: ='SC4 Data'!L6 -> 0.36 | I21: ='SC4 Data'!Q6 -> 0.34 | J21: ='SC4 Data'!V6 -> 0.43 | K21: ='SC4 Data'!AA6 -> 0.52763819 | L21: ='SC4 Data'!AF6 -> 0.59 | M21: ='SC4 Data'!AK6 -> 0
A22: 5 | B22: SC4 – S02 - Collected (Actual) | C22: high | D22: Completeness (Critical) | G22: ='SC4 Data'!F7 -> 0.92 | H22: ='SC4 Data'!K7 -> 0.95 | I22: ='SC4 Data'!P7 -> 0.88 | J22: ='SC4 Data'!U7 -> 0.9 | K22: ='SC4 Data'!Z7 -> 0.88944724 | L22: ='SC4 Data'!AE7 -> 0.9 | M22: ='SC4 Data'!AJ7 -> 0
A23: 6 | B23: SC4 – S02 - Collected (Actual) | C23: high | D23: Timeliness (Critical) | G23: ='SC4 Data'!G7 -> 0.17 | H23: ='SC4 Data'!L7 -> 0.39 | I23: ='SC4 Data'!Q7 -> 0.34 | J23: ='SC4 Data'!V7 -> 0.4 | K23: ='SC4 Data'!AA7 -> 0.32914573 | L23: ='SC4 Data'!AF7 -> 0.37 | M23: ='SC4 Data'!AK7 -> 0
A24: 7 | B24: SC4 – S46 - Documents rcvd from shipper (Actual) | C24: medium | D24: Completeness (All) | G24: ='SC4 Data'!F8 -> 0.61 | H24: ='SC4 Data'!K8 -> 0.37 | I24: ='SC4 Data'!P8 -> 0.41 | J24: ='SC4 Data'!U8 -> 0.61 | K24: ='SC4 Data'!Z8 -> 0.67741935 | L24: ='SC4 Data'!AE8 -> 0.73 | M24: ='SC4 Data'!AJ8 -> 0
A25: 8 | B25: SC4 – S46 - Documents rcvd from shipper (Actual) | C25: medium | D25: Timeliness (All) | G25: ='SC4 Data'!G8 -> 0.27 | H25: ='SC4 Data'!L8 -> 0.18 | I25: ='SC4 Data'!Q8 -> 0.15 | J25: ='SC4 Data'!V8 -> 0.31 | K25: ='SC4 Data'!AA8 -> 0.31309298 | L25: ='SC4 Data'!AF8 -> 0.41 | M25: ='SC4 Data'!AK8 -> 0
A26: 9 | B26: SC4 – S10 - On hand at origin SVC (Actual) | C26: medium | D26: Completeness (All) | G26: ='SC4 Data'!F9 -> 0.96 | H26: ='SC4 Data'!K9 -> 0.91 | I26: ='SC4 Data'!P9 -> 0.83 | J26: ='SC4 Data'!U9 -> 0.88 | K26: ='SC4 Data'!Z9 -> 0.8131068 | L26: ='SC4 Data'!AE9 -> 0.9 | M26: ='SC4 Data'!AJ9 -> 0
A27: 10 | B27: SC4 – S10 - On hand at origin SVC (Actual) | C27: medium | D27: Timeliness (All) | G27: ='SC4 Data'!G9 -> 0.64 | H27: ='SC4 Data'!L9 -> 0.53 | I27: ='SC4 Data'!Q9 -> 0.51 | J27: ='SC4 Data'!V9 -> 0.49 | K27: ='SC4 Data'!AA9 -> 0.47087379 | L27: ='SC4 Data'!AF9 -> 0.53 | M27: ='SC4 Data'!AK9 -> 0
A28: 11 | B28: SC4 – S11 - On hand at origin Hub/CC (Actual) | C28: medium | D28: Completeness (All) | G28: ='SC4 Data'!F10 -> 0.68 | H28: ='SC4 Data'!K10 -> 0.44 | I28: ='SC4 Data'!P10 -> 0.46 | J28: ='SC4 Data'!U10 -> 0.68 | K28: ='SC4 Data'!Z10 -> 0.70873786 | L28: ='SC4 Data'!AE10 -> 0.82 | M28: ='SC4 Data'!AJ10 -> 0
A29: 12 | B29: SC4 – S11 - On hand at origin Hub/CC (Actual) | C29: medium | D29: Timeliness (All) | G29: ='SC4 Data'!G10 -> 0.47 | H29: ='SC4 Data'!L10 -> 0.27 | I29: ='SC4 Data'!Q10 -> 0.3 | J29: ='SC4 Data'!V10 -> 0.36 | K29: ='SC4 Data'!AA10 -> 0.39805825 | L29: ='SC4 Data'!AF10 -> 0.45 | M29: ='SC4 Data'!AK10 -> 0
A30: 13 | B30: SC4 – S16 - Shipment booked with carrier (Actual) | C30: medium | D30: Completeness (All) | G30: ='SC4 Data'!F11 -> 0.71 | H30: ='SC4 Data'!K11 -> 0.61 | I30: ='SC4 Data'!P11 -> 0.61 | J30: ='SC4 Data'!U11 -> 0.75 | K30: ='SC4 Data'!Z11 -> 0.76850095 | L30: ='SC4 Data'!AE11 -> 0.79 | M30: ='SC4 Data'!AJ11 -> 0
A31: 14 | B31: SC4 – S16 - Shipment booked with carrier (Actual) | C31: medium | D31: Timeliness (All) | G31: ='SC4 Data'!G11 -> 0.51 | H31: ='SC4 Data'!L11 -> 0.47 | I31: ='SC4 Data'!Q11 -> 0.48 | J31: ='SC4 Data'!V11 -> 0.61 | K31: ='SC4 Data'!AA11 -> 0.61100569 | L31: ='SC4 Data'!AF11 -> 0.67 | M31: ='SC4 Data'!AK11 -> 0
A32: 15 | B32: SC4 – S17 - Tendered carrier (Actual) | C32: medium | D32: Completeness (All) | G32: ='SC4 Data'!F12 -> 0.7 | H32: ='SC4 Data'!K12 -> 0.42 | I32: ='SC4 Data'!P12 -> 0.42 | J32: ='SC4 Data'!U12 -> 0.57 | K32: ='SC4 Data'!Z12 -> 0.59466019 | L32: ='SC4 Data'!AE12 -> 0.62 | M32: ='SC4 Data'!AJ12 -> 0
A33: 16 | B33: SC4 – S17 - Tendered carrier (Actual) | C33: medium | D33: Timeliness (All) | G33: ='SC4 Data'!G12 -> 0.29 | H33: ='SC4 Data'!L12 -> 0.27 | I33: ='SC4 Data'!Q12 -> 0.17 | J33: ='SC4 Data'!V12 -> 0.3 | K33: ='SC4 Data'!AA12 -> 0.3276699 | L33: ='SC4 Data'!AF12 -> 0.36 | M33: ='SC4 Data'!AK12 -> 0
A34: 17 | B34: SC4 – S50 - Received origin CFS (Actual) | C34: medium | D34: Completeness (All) | G34: ='SC4 Data'!F13 -> 0.9 | H34: ='SC4 Data'!K13 -> 0.92 | I34: ='SC4 Data'!P13 -> 0.77 | J34: ='SC4 Data'!U13 -> 0.71 | K34: ='SC4 Data'!Z13 -> 0.78923767 | L34: ='SC4 Data'!AE13 -> 0.67 | M34: ='SC4 Data'!AJ13 -> 0
A35: 18 | B35: SC4 – S50 - Received origin CFS (Actual) | C35: medium | D35: Timeliness (All) | G35: ='SC4 Data'!G13 -> 0.4 | H35: ='SC4 Data'!L13 -> 0.64 | I35: ='SC4 Data'!Q13 -> 0.42 | J35: ='SC4 Data'!V13 -> 0.33 | K35: ='SC4 Data'!AA13 -> 0.43946188 | L35: ='SC4 Data'!AF13 -> 0.44 | M35: ='SC4 Data'!AK13 -> 0
A36: 19 | B36: SC4 – S04 - Vessel/flight departed (Estimated) | C36: high | D36: Completeness (Critical) | G36: ='SC4 Data'!F14 -> 0.99 | H36: ='SC4 Data'!K14 -> 0.99 | I36: ='SC4 Data'!P14 -> 0.96 | J36: ='SC4 Data'!U14 -> 0.97 | K36: ='SC4 Data'!Z14 -> 0.95635674 | L36: ='SC4 Data'!AE14 -> 0.97 | M36: ='SC4 Data'!AJ14 -> 0
A37: 20 | B37: SC4 – S04 - Vessel/flight departed (Estimated) | C37: high | D37: Timeliness (Critical) | G37: ='SC4 Data'!G14 -> 0.38 | H37: ='SC4 Data'!L14 -> 0.43 | I37: ='SC4 Data'!Q14 -> 0.37 | J37: ='SC4 Data'!V14 -> 0.43 | K37: ='SC4 Data'!AA14 -> 0.48766603 | L37: ='SC4 Data'!AF14 -> 0.53 | M37: ='SC4 Data'!AK14 -> 0
A38: 21 | B38: SC4 – S04 - Vessel/flight departed (Actual) | C38: high | D38: Completeness (Critical) | G38: ='SC4 Data'!F15 -> 0.96 | H38: ='SC4 Data'!K15 -> 0.93 | I38: ='SC4 Data'!P15 -> 0.83 | J38: ='SC4 Data'!U15 -> 0.88 | K38: ='SC4 Data'!Z15 -> 0.89373814 | L38: ='SC4 Data'!AE15 -> 0.88 | M38: ='SC4 Data'!AJ15 -> 0
A39: 22 | B39: SC4 – S04 - Vessel/flight departed (Actual) | C39: high | D39: Timeliness (Critical) | G39: ='SC4 Data'!G15 -> 0.83 | H39: ='SC4 Data'!L15 -> 0.55 | I39: ='SC4 Data'!Q15 -> 0.52 | J39: ='SC4 Data'!V15 -> 0.54 | K39: ='SC4 Data'!AA15 -> 0.4914611 | L39: ='SC4 Data'!AF15 -> 0.58 | M39: ='SC4 Data'!AK15 -> 0
A40: 23 | B40: SC4 – S07 - Vessel/flight arrived (Estimated) | C40: high | D40: Completeness (Critical) | G40: ='SC4 Data'!F16 -> 1 | H40: ='SC4 Data'!K16 -> 0.96 | I40: ='SC4 Data'!P16 -> 0.93 | J40: ='SC4 Data'!U16 -> 0.94 | K40: ='SC4 Data'!Z16 -> 0.92789374 | L40: ='SC4 Data'!AE16 -> 0.96 | M40: ='SC4 Data'!AJ16 -> 0
...

Sheet SC4 Data
A1: SC4 - Weekly Milestone Data
A2: Critical Milestones: S00, S02, S04, S07, S31, S45
C3: Week 1 | H3: Week 2 | M3: Week 3 | R3: Week 4 | W3: Week 5 | AB3: Week 6
A4: Milestone | B4: Type | C4: Required | D4: Available | E4: In Time | F4: Completeness | G4: Timeliness | H4: Required | I4: Available | J4: In Time | K4: Completeness | L4: Timeliness | M4: Required | N4: Available | O4: In Time | P4: Completeness | Q4: Timeliness | R4: Required | S4: Available | T4: In Time | U4: Completeness | V4: Timeliness | W4: Required | X4: Available | Y4: In Time | Z4: Completeness | AA4: Timeliness | AB4: Required | AC4: Available | AD4: In Time | AE4: Completeness | AF4: Timeliness
A5: S00 - Shipment created | B5: Actual | C5: 168 | D5: 88 | E5: 88 | F5: 0.52 | G5: 0.52 | H5: 390 | I5: 141 | J5: 139 | K5: 0.36 | L5: 0.36 | M5: 675 | N5: 236 | O5: 233 | P5: 0.35 | Q5: 0.35 | R5: 719 | S5: 358 | T5: 352 | U5: 0.5 | V5: 0.49 | W5: 527 | X5: 291 | Y5: 288 | Z5: 0.55218216 | AA5: 0.54648956 | AB5: 569 | AC5: 349 | AD5: 341 | AE5: 0.61 | AF5: 0.6
A6: S02 - Collected | B6: Estimated | C6: 145 | D6: 114 | E6: 59 | F6: 0.79 | G6: 0.41 | H6: 286 | I6: 237 | J6: 104 | K6: 0.83 | L6: 0.36 | M6: 496 | N6: 423 | O6: 167 | P6: 0.85 | Q6: 0.34 | R6: 514 | S6: 447 | T6: 220 | U6: 0.87 | V6: 0.43 | W6: 398 | X6: 337 | Y6: 210 | Z6: 0.84673367 | AA6: 0.52763819 | AB6: 399 | AC6: 359 | AD6: 234 | AE6: 0.9 | AF6: 0.59
A7: S02 - Collected | B7: Actual | C7: 145 | D7: 133 | E7: 24 | F7: 0.92 | G7: 0.17 | H7: 286 | I7: 272 | J7: 112 | K7: 0.95 | L7: 0.39 | M7: 496 | N7: 438 | O7: 171 | P7: 0.88 | Q7: 0.34 | R7: 514 | S7: 462 | T7: 207 | U7: 0.9 | V7: 0.4 | W7: 398 | X7: 354 | Y7: 131 | Z7: 0.88944724 | AA7: 0.32914573 | AB7: 399 | AC7: 361 | AD7: 149 | AE7: 0.9 | AF7: 0.37
A8: S46 - Documents rcvd from shipper | B8: Actual | C8: 168 | D8: 103 | E8: 45 | F8: 0.61 | G8: 0.27 | H8: 390 | I8: 144 | J8: 72 | K8: 0.37 | L8: 0.18 | M8: 675 | N8: 277 | O8: 104 | P8: 0.41 | Q8: 0.15 | R8: 719 | S8: 435 | T8: 226 | U8: 0.61 | V8: 0.31 | W8: 527 | X8: 357 | Y8: 165 | Z8: 0.67741935 | AA8: 0.31309298 | AB8: 569 | AC8: 418 | AD8: 235 | AE8: 0.73 | AF8: 0.41
A9: S10 - On hand at origin SVC | B9: Actual | C9: 154 | D9: 148 | E9: 98 | F9: 0.96 | G9: 0.64 | H9: 335 | I9: 305 | J9: 177 | K9: 0.91 | L9: 0.53 | M9: 535 | N9: 443 | O9: 274 | P9: 0.83 | Q9: 0.51 | R9: 577 | S9: 505 | T9: 281 | U9: 0.88 | V9: 0.49 | W9: 412 | X9: 335 | Y9: 194 | Z9: 0.8131068 | AA9: 0.47087379 | AB9: 461 | AC9: 413 | AD9: 243 | AE9: 0.9 | AF9: 0.53
A10: S11 - On hand at origin Hub/ CC | B10: Actual | C10: 154 | D10: 104 | E10: 73 | F10: 0.68 | G10: 0.47 | H10: 335 | I10: 146 | J10: 92 | K10: 0.44 | L10: 0.27 | M10: 535 | N10: 245 | O10: 160 | P10: 0.46 | Q10: 0.3 | R10: 577 | S10: 390 | T10: 205 | U10: 0.68 | V10: 0.36 | W10: 412 | X10: 292 | Y10: 164 | Z10: 0.70873786 | AA10: 0.39805825 | AB10: 461 | AC10: 376 | AD10: 207 | AE10: 0.82 | AF10: 0.45
A11: S16 - Shipment booked with carrier | B11: Actual | C11: 168 | D11: 119 | E11: 86 | F11: 0.71 | G11: 0.51 | H11: 390 | I11: 237 | J11: 183 | K11: 0.61 | L11: 0.47 | M11: 675 | N11: 415 | O11: 323 | P11: 0.61 | Q11: 0.48 | R11: 719 | S11: 539 | T11: 439 | U11: 0.75 | V11: 0.61 | W11: 527 | X11: 405 | Y11: 322 | Z11: 0.76850095 | AA11: 0.61100569 | AB11: 569 | AC11: 451 | AD11: 384 | AE11: 0.79 | AF11: 0.67
A12: S17 - Tendered carrier | B12: Actual | C12: 154 | D12: 108 | E12: 44 | F12: 0.7 | G12: 0.29 | H12: 335 | I12: 141 | J12: 89 | K12: 0.42 | L12: 0.27 | M12: 535 | N12: 225 | O12: 89 | P12: 0.42 | Q12: 0.17 | R12: 577 | S12: 328 | T12: 172 | U12: 0.57 | V12: 0.3 | W12: 412 | X12: 245 | Y12: 135 | Z12: 0.59466019 | AA12: 0.3276699 | AB12: 461 | AC12: 286 | AD12: 165 | AE12: 0.62 | AF12: 0.36
A13: S50 - Received origin CFS | B13: Actual | C13: 115 | D13: 104 | E13: 46 | F13: 0.9 | G13: 0.4 | H13: 190 | I13: 175 | J13: 122 | K13: 0.92 | L13: 0.64 | M13: 354 | N13: 273 | O13: 149 | P13: 0.77 | Q13: 0.42 | R13: 294 | S13: 208 | T13: 96 | U13: 0.71 | V13: 0.33 | W13: 223 | X13: 176 | Y13: 98 | Z13: 0.78923767 | AA13: 0.43946188 | AB13: 183 | AC13: 122 | AD13: 81 | AE13: 0.67 | AF13: 0.44
A14: S04 - Vessel/ flight departed | B14: Estimated | C14: 168 | D14: 166 | E14: 63 | F14: 0.99 | G14: 0.38 | H14: 390 | I14: 385 | J14: 166 | K14: 0.99 | L14: 0.43 | M14: 675 | N14: 648 | O14: 248 | P14: 0.96 | Q14: 0.37 | R14: 719 | S14: 696 | T14: 308 | U14: 0.97 | V14: 0.43 | W14: 527 | X14: 504 | Y14: 257 | Z14: 0.95635674 | AA14: 0.48766603 | AB14: 569 | AC14: 551 | AD14: 303 | AE14: 0.97 | AF14: 0.53
A15: S04 - Vessel/ flight departed | B15: Actual | C15: 168 | D15: 161 | E15: 140 | F15: 0.96 | G15: 0.83 | H15: 390 | I15: 362 | J15: 213 | K15: 0.93 | L15: 0.55 | M15: 675 | N15: 563 | O15: 353 | P15: 0.83 | Q15: 0.52 | R15: 719 | S15: 630 | T15: 385 | U15: 0.88 | V15: 0.54 | W15: 527 | X15: 471 | Y15: 259 | Z15: 0.89373814 | AA15: 0.4914611 | AB15: 569 | AC15: 500 | AD15: 332 | AE15: 0.88 | AF15: 0.58
A16: S07 - Vessel/ flight arrived | B16: Estimated | C16: 168 | D16: 168 | E16: 43 | F16: 1 | G16: 0.26 | H16: 390 | I16: 376 | J16: 83 | K16: 0.96 | L16: 0.21 | M16: 675 | N16: 631 | O16: 124 | P16: 0.93 | Q16: 0.18 | R16: 719 | S16: 679 | T16: 159 | U16: 0.94 | V16: 0.22 | W16: 527 | X16: 489 | Y16: 113 | Z16: 0.92789374 | AA16: 0.21442125 | AB16: 569 | AC16: 547 | AD16: 75 | AE16: 0.96 | AF16: 0.13
... A25: S31 - Delivered | B25: Actual | C25: 50 | D25: 50 | E25: 2 | F25: 1 | G25: 0.04 | H25: 261 | I25: 261 | J25: 32 | K25: 1 | L25: 0.12 | M25: 462 | N25: 353 | O25: 132 | P25: 0.76 | Q25: 0.29 | R25: 535 | S25: 445 | T25: 48 | U25: 0.83 | V25: 0.09 | W25: 418 | X25: 351 | Y25: 44 | Z25: 0.83971292 | AA25: 0.10526316 | AB25: 459 | AC25: 304 | AD25: 73 | AE25: 0.66 | AF25: 0.16

Sheet SC3 Data
A1: SC3 - Weekly Milestone Data
A2: Critical Milestones: S02, S04, S07, S31, S45
C3: Week 1 | H3: Week 2 | M3: Week 3 | R3: Week 4 | W3: Week 5 | AB3: Week 6
A4: Milestone | B4: Type | C4: Required | D4: Available | E4: In Time | F4: Completeness | G4: Timeliness | H4: Required | I4: Available | J4: In Time | K4: Completeness | L4: Timeliness | M4: Required | N4: Available | O4: In Time | P4: Completeness | Q4: Timeliness | R4: Required | S4: Available | T4: In Time | U4: Completeness | V4: Timeliness | W4: Required | X4: Available | Y4: In Time | Z4: Completeness | AA4: Timeliness | AB4: Required | AC4: Available | AD4: In Time | AE4: Completeness | AF4: Timeliness
A5: S60 - Pre-Booking confirmed | B5: Actual | C5: 29 | D5: 27 | E5: 27 | F5: 0.931 | G5: 0.931 | H5: 36 | I5: 33 | J5: 33 | K5: 0.917 | L5: 0.917 | M5: 51 | N5: 47 | O5: 47 | P5: 0.922 | Q5: 0.922 | R5: 66 | S5: 63 | T5: 62 | U5: 0.955 | V5: 0.939 | W5: 52 | X5: 48 | Y5: 48 | Z5: 0.92307692 | AA5: 0.92307692 | AB5: 76 | AC5: 70 | AD5: 70 | AE5: 0.921 | AF5: 0.921
A6: S52 - Empty Container picked up | B6: Actual | C6: 26 | D6: 7 | E6: 5 | F6: 0.269 | G6: 0.192 | H6: 27 | I6: 8 | J6: 6 | K6: 0.296 | L6: 0.222 | M6: 47 | N6: 14 | O6: 12 | P6: 0.298 | Q6: 0.255 | R6: 52 | S6: 10 | T6: 6 | U6: 0.192 | V6: 0.115 | W6: 45 | X6: 13 | Y6: 11 | Z6: 0.28888889 | AA6: 0.24444444 | AB6: 46 | AC6: 14 | AD6: 6 | AE6: 0.304 | AF6: 0.13
A7: S02 - Collected | B7: Actual | C7: 240 | D7: 195 | E7: 76 | F7: 0.813 | G7: 0.317 | H7: 283 | I7: 224 | J7: 111 | K7: 0.792 | L7: 0.392 | M7: 289 | N7: 211 | O7: 92 | P7: 0.73 | Q7: 0.318 | R7: 306 | S7: 242 | T7: 97 | U7: 0.791 | V7: 0.317 | W7: 292 | X7: 221 | Y7: 100 | Z7: 0.75684932 | AA7: 0.34246575 | AB7: 304 | AC7: 239 | AD7: 117 | AE7: 0.786 | AF7: 0.385
A8: S02 - Collected | B8: Estimated | C8: 214 | D8: 174 | E8: 0 | F8: 0.813 | G8: 0 | H8: 256 | I8: 207 | J8: 0 | K8: 0.809 | L8: 0 | M8: 242 | N8: 188 | O8: 0 | P8: 0.777 | Q8: 0 | R8: 254 | S8: 213 | T8: 0 | U8: 0.839 | V8: 0 | W8: 247 | X8: 205 | Y8: 0 | Z8: 0.82995951 | AA8: 0 | AB8: 258 | AC8: 219 | AD8: 0 | AE8: 0.849 | AF8: 0
A9: S10 - On hand at origin SVC | B9: Actual | C9: 146 | D9: 138 | E9: 95 | F9: 0.945 | G9: 0.651 | H9: 208 | I9: 194 | J9: 114 | K9: 0.933 | L9: 0.548 | M9: 181 | N9: 162 | O9: 105 | P9: 0.895 | Q9: 0.58 | R9: 198 | S9: 176 | T9: 97 | U9: 0.889 | V9: 0.49 | W9: 183 | X9: 171 | Y9: 108 | Z9: 0.93442623 | AA9: 0.59016393 | AB9: 216 | AC9: 195 | AD9: 104 | AE9: 0.903 | AF9: 0.481
A10: S50 - Received origin CFS | B10: Actual | C10: 107 | D10: 84 | E10: 75 | F10: 0.785 | G10: 0.701 | H10: 115 | I10: 90 | J10: 82 | K10: 0.783 | L10: 0.713 | M10: 125 | N10: 97 | O10: 84 | P10: 0.776 | Q10: 0.672 | R10: 153 | S10: 106 | T10: 100 | U10: 0.693 | V10: 0.654 | W10: 147 | X10: 117 | Y10: 104 | Z10: 0.79591837 | AA10: 0.70748299 | AB10: 150 | AC10: 96 | AD10: 74 | AE10: 0.64 | AF10: 0.493
A11: S53 - Full Container loaded on vessel | B11: Actual | C11: 29 | D11: 12 | E11: 11 | F11: 0.414 | G11: 0.379 | H11: 36 | I11: 15 | J11: 14 | K11: 0.417 | L11: 0.389 | M11: 51 | N11: 26 | O11: 25 | P11: 0.51 | Q11: 0.49 | R11: 66 | S11: 28 | T11: 23 | U11: 0.424 | V11: 0.348 | W11: 54 | X11: 37 | Y11: 34 | Z11: 0.68518519 | AA11: 0.62962963 | AB11: 78 | AC11: 46 | AD11: 43 | AE11: 0.59 | AF11: 0.551
A12: S04 - Vessel/ flight departed | B12: Actual | C12: 253 | D12: 219 | E12: 217 | F12: 0.866 | G12: 0.858 | H12: 323 | I12: 279 | J12: 277 | K12: 0.864 | L12: 0.858 | M12: 306 | N12: 258 | O12: 250 | P12: 0.843 | Q12: 0.817 | R12: 351 | S12: 281 | T12: 274 | U12: 0.801 | V12: 0.781 | W12: 330 | X12: 301 | Y12: 294 | Z12: 0.91212121 | AA12: 0.89090909 | AB12: 366 | AC12: 311 | AD12: 304 | AE12: 0.85 | AF12: 0.831
A13: S04 - Vessel/ flight departed | B13: Estimated | C13: 253 | D13: 219 | E13: 174 | F13: 0.866 | G13: 0.688 | H13: 323 | I13: 289 | J13: 234 | K13: 0.895 | L13: 0.724 | M13: 306 | N13: 264 | O13: 216 | P13: 0.863 | Q13: 0.706 | R13: 351 | S13: 297 | T13: 239 | U13: 0.846 | V13: 0.681 | W13: 330 | X13: 301 | Y13: 268 | Z13: 0.91212121 | AA13: 0.81212121 | AB13: 366 | AC13: 307 | AD13: 259 | AE13: 0.839 | AF13: 0.708
A14: S07 - Vessel/ flight arrived | B14: Actual | C14: 253 | D14: 229 | E14: 224 | F14: 0.905 | G14: 0.885 | H14: 323 | I14: 291 | J14: 287 | K14: 0.901 | L14: 0.889 | M14: 306 | N14: 264 | O14: 260 | P14: 0.863 | Q14: 0.85 | R14: 351 | S14: 302 | T14: 298 | U14: 0.86 | V14: 0.849 | W14: 330 | X14: 308 | Y14: 307 | Z14: 0.93333333 | AA14: 0.93030303 | AB14: 366 | AC14: 320 | AD14: 316 | AE14: 0.874 | AF14: 0.863
A15: S07 - Vessel/ flight arrived | B15: Estimated | C15: 253 | D15: 223 | E15: 211 | F15: 0.881 | G15: 0.834 | H15: 323 | I15: 295 | J15: 279 | K15: 0.913 | L15: 0.864 | M15: 306 | N15: 269 | O15: 254 | P15: 0.879 | Q15: 0.83 | R15: 351 | S15: 304 | T15: 290 | U15: 0.866 | V15: 0.826 | W15: 330 | X15: 309 | Y15: 294 | Z15: 0.93636364 | AA15: 0.89090909 | AB15: 366 | AC15: 325 | AD15: 303 | AE15: 0.888 | AF15: 0.828
A16: S54 - Full Container discharge from vessel | B16: Actual | C16: 29 | D16: 4 | E16: 2 | F16: 0.138 | G16: 0.069 | H16: 36 | I16: 5 | J16: 5 | K16: 0.139 | L16: 0.139 | M16: 51 | N16: 2 | O16: 0 | P16: 0.039 | Q16: 0 | R16: 66 | S16: 3 | T16: 3 | U16: 0.045 | V16: 0.045 | W16: 54 | X16: 4 | Y16: 3 | Z16: 0.074074074 | AA16: 0.055555556 | AB16: 78 | AC16: 2 | AD16: 2 | AE16: 0.026 | AF16: 0.026
... A24: S55 - Empty Container returned | B24: Actual | C24: 28 | D24: 10 | E24: 7 | F24: 0.357 | G24: 0.25 | H24: 36 | I24: 24 | J24: 20 | K24: 0.667 | L24: 0.556 | M24: 50 | N24: 31 | O24: 26 | P24: 0.62 | Q24: 0.52 | R24: 64 | S24: 42 | T24: 40 | U24: 0.656 | V24: 0.625 | W24: 52 | X24: 40 | Y24: 40 | Z24: 0.76923077 | AA24: 0.76923077 | AB24: 77 | AC24: 61 | AD24: 60 | AE24: 0.792 | AF24: 0.779

Sheet Current State
A1: MAERSK Milestone Performance - Current State Analysis
A3: Overall Performance Summary
A5: Metric | B5: Current | C5: Target | D5: Gap
A6: Total Status Codes Required | B6: 43415 | C6: 43415 | D6: 0
A7: Overall Completion Rate | B7: 0.66497754 | C7: 0.95 | D7: 0.28502246
A8: Overall Timeliness Rate | B8: 0.41206956 | C8: 0.95 | D8: 0.53793044
A11: Milestone Performance Details
A13: Milestone | B13: Required | C13: Available | D13: In Time | E13: Completion % | F13: Timeliness % | G13: Completion Gap | H13: Timeliness Gap | I13: Total Impact | J13: Cumulative %
A14: S02 - Collected | B14: 5502 | C14: 4621 | D14: 1140 | E14: 0.83987641 | F14: 0.20719738 | G14: 0.11012359 | H14: 0.74280262 | I14: 4692.8 | J14: 0.131
A15: S31 - Delivered | B15: 4464 | C15: 3387 | D15: 1761 | E15: 0.75873656 | F15: 0.39448925 | G15: 0.19126344 | H15: 0.55551075 | I15: 3333.6 | J15: 0.225
A16: S13 - On hand at destination SVC | B16: 1779 | C16: 139 | D16: 89 | E16: 0.078133783 | F16: 0.050028106 | G16: 0.87186622 | H16: 0.89997189 | I16: 3152.1 | J16: 0.313
A17: S05 - In delivery | B17: 2232 | C17: 686 | D17: 542 | E17: 0.30734767 | F17: 0.24283154 | G17: 0.64265233 | H17: 0.70716846 | I17: 3012.8 | J17: 0.397
A18: S07 - Vessel/ flight arrived | B18: 6636 | C18: 5890 | D18: 4338 | E18: 0.88758288 | F18: 0.65370705 | G18: 0.062417119 | H18: 0.29629295 | I18: 2380.4 | J18: 0.464
A19: S04 - Vessel/ flight departed | B19: 6636 | C19: 6029 | D19: 4326 | E19: 0.90852923 | F19: 0.65189873 | G19: 0.041470766 | H19: 0.29810127 | I19: 2253.4 | J19: 0.527
A20: S51 - Arrived destination CFS | B20: 1539 | C20: 479 | D20: 322 | E20: 0.31124107 | F20: 0.20922677 | G20: 0.63875893 | H20: 0.74077323 | I20: 2123.1 | J20: 0.586
A21: S46 - Documents rcvd from shipper | B21: 1372 | C21: 427 | D21: 179 | E21: 0.31122449 | F21: 0.13046647 | G21: 0.63877551 | H21: 0.81953353 | I21: 2000.8 | J21: 0.642
A22: S00 - Shipment created | B22: 1372 | C22: 412 | D22: 406 | E22: 0.30029155 | F22: 0.29591837 | G22: 0.64970845 | H22: 0.65408163 | I22: 1788.8 | J22: 0.692
A23: S17 - Tendered carrier | B23: 1200 | C23: 419 | D23: 204 | E23: 0.34916667 | F23: 0.17 | G23: 0.60083333 | H23: 0.78 | I23: 1657 | J23: 0.739
A24: S11 - On hand at origin Hub/ CC | B24: 1200 | C24: 433 | D24: 297 | E24: 0.36083333 | F24: 0.2475 | G24: 0.58916667 | H24: 0.7025 | I24: 1550 | J24: 0.782
A25: S16 - Shipment booked with carrier | B25: 1372 | C25: 715 | D25: 551 | E25: 0.52113703 | F25: 0.4016035 | G25: 0.42886297 | H25: 0.5483965 | I25: 1340.8 | J25: 0.82
... A36: S61 - Pre-Booking declined | B36: 2 | C36: 2 | D36: 0 | E36: 1 | F36: 0 | G36: -0.05 | H36: 0.95 | I36: 1.8 | J36: 1

Sheet Pareto Analysis
A1: Pareto Analysis - 80/20 Impact
A3: Key Insight: Top 11 milestones (48% of total) contribute 80% of the performance impact
A5: Rank | B5: Milestone | C5: Total Impact | D5: Cumulative Impact | E5: Cumulative %
A6: 1 | B6: S02 - Collected | C6: 4692.8 | D6: 4692.8 | E6: 0.131 | F6: Critical
A7: 2 | B7: S31 - Delivered | C7: 3333.6 | D7: 8026.4 | E7: 0.225 | F7: Critical
A8: 3 | B8: S13 - On hand at destination SVC | C8: 3152.1 | D8: 11178.5 | E8: 0.313
A9: 4 | B9: S05 - In delivery | C9: 3012.8 | D9: 14191.3 | E9: 0.397 | F9: Container Level
A10: 5 | B10: S07 - Vessel/ flight arrived | C10: 2380.4 | D10: 16571.7 | E10: 0.464 | F10: Critical
A11: 6 | B11: S04 - Vessel/ flight departed | C11: 2253.4 | D11: 18825.1 | E11: 0.527 | F11: Critical
A12: 7 | B12: S51 - Arrived destination CFS | C12: 2123.1 | D12: 20948.2 | E12: 0.586 | F12: Container Level
A13: 8 | B13: S46 - Documents rcvd from shipper | C13: 2000.8 | D13: 22949 | E13: 0.642
A14: 9 | B14: S00 - Shipment created | C14: 1788.8 | D14: 24737.8 | E14: 0.692 | F14: Critical
A15: 10 | B15: S17 - Tendered carrier | C15: 1657 | D15: 26394.8 | E15: 0.739 | F15: Container Level
A16: 11 | B16: S11 - On hand at origin Hub/ CC | C16: 1550 | D16: 27944.8 | E16: 0.782
A17: 12 | B17: S16 - Shipment booked with carrier | C17: 1340.8 | D17: 29285.6 | E17: 0.82
A18: 13 | B18: S45 - Handover to broker | C18: 1234.6 | D18: 30520.2 | E18: 0.854
A19: 14 | B19: S18 - Recovered from carrier | C19: 1124.9 | D19: 31645.1 | E19: 0.886
A20: 15 | B20: S12 - On hand at destination Hub/ CC | C20: 966.9 | D20: 32612 | E20: 0.913
A21: 16 | B21: S10 - On hand at origin SVC | C21: 862.2 | D21: 33474.2 | E21: 0.937
A22: 17 | B22: S50 - Received origin CFS | C22: 808.1 | D22: 34282.3 | E22: 0.96
A23: 18 | B23: S54 - Full Container discharge from vessel | C23: 478.5 | D23: 34760.8 | E23: 0.973
A24: 19 | B24: S52 - Empty Container picked up | C24: 346 | D24: 35106.8 | E24: 0.983
A25: 20 | B25: S53 - Full Container loaded on vessel | C25: 293.5 | D25: 35400.3 | E25: 0.991
A26: 21 | B26: S55 - Empty Container returned | C26: 285.5 | D26: 35685.8 | E26: 0.999
A27: 22 | B27: S60 - Pre-Booking confirmed | C27: 40.9 | D27: 35726.7 | E27: 1
A28: 23 | B28: S61 - Pre-Booking declined | C28: 1.8 | D28: 35728.5 | E28: 1

Sheet Regional actions
A1: Region | B1: Action Item | C1: Metrics | D1: Priority | E1: Owner | F1: Name | G1: ETA | H1: Status
A2: EUR | B2: Check and confirm resourcing and FTE capacity to reach target by end April for the 3 areas: NEC, EME and CSE | C2: Missing Milestones | D2: P0 | E2: Area and Region LCL Ops leader | F2: Christine Kühl | G2: 46058 | H2: Completed, all areas confirmed capacity needs and approvals needed.
A3: APA | B3: Check and confirm resourcing and FTE capacity to reach target by end April for the 3 areas: GCA, SEA, MEK | D3: P0 | E3: Area and Region LCL Ops leader | F3: Jos Raaymakers | G3: 46058 | H3: SEA confirmed capacity. GCA to confirm back by 06-Feb.
A4: EUR | B4: Improve reporting quality of milestone completeness (with filters) to enable operations to be proactive. | D4: P0 | E4: Central reporting team | F4: Christine Kühl | G4: 46062 | H4: Daily reporting to be enhanced for ops to be more proactive. Call on Monday to be followed by report refining.
A5: GCA | B5: Conduct root cause analysis for 1195 missing milestones | C5: Missing Milestones | D5: P0 | E5: Regional Ops Lead | F5: Jos Raaymakers | G5: 46054 | H5: In Progress
A6: GCA | B6: Implement mandatory field validation at booking for 1446 milestones | C6: Missing Mandatory | D6: P0 | E6: Regional Ops Lead | F6: Jos Raaymakers | G6: 46054 | H6: Not Started
A7: CSE | B7: Reverse declining trend (661→701) milestones missing - Stop the bleeding | C7: Missing Milestones | D7: P0 | E7: Regional Ops Lead | F7: Christine Kühl | G7: 46054 | H7: Not Started
A8: CSE | B8: Fix 1521 missing mandatory information fields | C8: Missing Mandatory | D8: P0 | E8: Regional Ops Lead | F8: Christine Kühl | G8: 46054 | H8: Not Started
A9: NEC | B9: Continue improvement trend (892→753) - Accelerate | C9: Missing Milestones | D9: P0 | E9: Regional Ops Lead | F9: Christine Kühl | G9: 46054
A10: NEC | B10: Address 2676 mandatory info gaps (highest volume) | C10: Missing Mandatory | D10: P0 | E10: Data Quality Team | F10: Christine Kühl | G10: 46054 | H10: Not Started
A11: EME | B11: Sustain improvement | C11: Missing Milestones | D11: P1 | E11: Regional Ops Lead | F11: Christine Kühl | G11: 46054 | H11: In Progress
A12: EME | B12: Focus on Mandatory Fields missing (198) | C12: Missing Mandatory | D12: P1 | E12: Regional Ops Lead | F12: Christine Kühl | G12: 46054 | H12: In Progress
A13: SEA | B13: Reduce 275 missing milestones through standardization | C13: Missing Milestones | D13: P1 | E13: Regional Ops Lead | F13: Jos Raaymakers | G13: 46054 | H13: In Progress
A14: SEA | B14: Focus on Mandatory Fields (303) | C14: Missing Mandatory | F14: Jos Raaymakers | G14: 46054
A15: MEK | B15: Maintain strong performance (121 missing) - Monitor | C15: Missing Milestones | D15: P2 | E15: Regional Ops Lead | F15: Jos Raaymakers | G15: 46054 | H15: In Progress
A16: NEA | B16: Slight improvement opportunity (151→<100) | C16: Missing Milestones | D16: P2 | E16: Regional Ops Lead | F16: Jos Raaymakers | G16: 46054 | H16: Not Started

Sheet Targets
B2: Metrics name | C2: 2025.11 | D2: 2025.12 | F2: Week 4 | G2: 2026.04 Target | H2: 2026.04 Target
E3: Week 1-3 | G3: (Maersk proposal) | H3: (Bosch proposal) | I3: Comments
B4: Milestone Completeness ( S02,S04,S07,S31) | C4: 0.82 | D4: 0.84 | E4: 0.858 | F4: 0.865 | G4: 0.95 | H4: 0.95 | I4: ✅ ACHIEVABLE : - Fix top 3 Missing fields in CW1 (Process/Tech) - Path toward 80% SC3 booking (Bosch) - Sustainable fix by stricter validation in Workflows (Process/Tech)
B5: Milestone Timeliness ( S02,S04,S07,S31) | C5: 0.1 | D5: 0.22 | E5: 0.486 | F5: 0.455 | G5: ?? | H5: 0.95 | I5: ⚠️ STRETCH and EDI DEPENDENT: - 85% ONLY achievable at 80% SC3 (Bosch) - With Dedicated Control tower and proactive update we can hit Close to 60% (Operations)
B6: Milestone Completeness ( All) | C6: Not Measured | D6: Not Measured | E6: 0.858 | F6: 0.865 | G6: 0.9 | H6: 0.95 | I6: ✅ ACHIEVABLE - Fix top 3 Missing fields in CW1 yields 18,6 % increase - Can be achieved with due diligance from CT on proactively updating missing fields (Operations)
B7: Milestone Timeliness (All) | C7: Not Measured | D7: Not Measured | E7: 0.486 | F7: 0.455 | G7: ?? | H7: 0.95 | I7: ⚠️ EDI DEPENDENT - The timeliness metrics can't be met with current EDI ratio, SC3 booking needs to be at ~75% to hit 80 % timeliness or ~80% to achieve 85% timeliness
B8: SC4 Refrence Completeness | E8: 0.65 | F8: 0.65 | G8: ?? | H8: 0.95 | I8: -DN OR CIV Number at 91 % for Field present. But filtering out for Junk value it stands at 80 %; - Conversion of SC4 --> SC3 will drastically improve accuracy Data to be verifiied on wrong refrence by end of next week - Shared by Bosch on Wednesday EOD
B9: ETA accuracy/reliability 2P shipments | F9: 0.015 | H9: 0.95 | I9: Data to be analyzed by next week
B10: ETA accuracy/reliability 2D shipments | F10: 0.33 | H10: 0.95 | I10: Data to be analyzed by next week

Sheet ETA accuracy Port
A1: Port Shipment ETA Accuracy — January 2026 ARR
A2: 1235 Housebills with ARR in January 2026 | Dual-view: ≥7 Day Lead Time vs Any Lead Time
A4: VIEW 1: ETA Published ≥7 Days Before ARR | F4: VIEW 2: Latest ETA (Any Lead Time)
A6: Total Jan HBs | B6: With ≥7d ETA | C6: ETA <7d only | D6: No ETA | F6: Total Jan HBs | G6: With ETA | H6: Missing ETA | I6: Median Dev
A7: 1235 | B7: 65 | C7: 1165 | D7: 5 | F7: 1235 | G7: 1175 | H7: 5 | I7: 1.2h
A9: Of the 65 with ≥7d ETA: | F9: Of the 1175 with any ETA: | O9: =65/1235*100 -> 5.2631579
A10: Within ±48h | B10: 19 | C10: 29.2% | F10: Within ±48h | G10: 1091 | H10: 92.9%
A11: Late (ARR after ETA) | B11: 39 | C11: 60.0% | F11: Late (ARR after ETA) | G11: 77 | H11: 6.6%
A12: Early (ARR before ETA) | B12: 7 | C12: 10.8% | F12: Early (ARR before ETA) | G12: 7 | H12: 0.6%
A14: ≥7d Accuracy (of matched): 19/65 = 29.2% | F14: Any-lead Accuracy (of matched): 1091/1175 = 92.9%
A15: ≥7d Accuracy (overall): 19/1235 = 1.5% | F15: Any-lead Accuracy (overall): 1091/1235 = 88.3%
A16: Median deviation: 50.2h | Mean: 75.8h
A18: Category | B18: Count | F18: Category | G18: Count
A19: Within ±48h | B19: 19 | F19: Within ±48h | G19: 1091
A20: Late | B20: 39 | F20: Late | G20: 77
A21: Early | B21: 7 | F21: Early | G21: 7
A22: ETA <7d (no qualifying) | B22: 1165 | F22: Missing ETA | G22: 5
A23: No ETA | B23: 5

Sheet POD estimate Accuracy
A1: Door Shipment POD Accuracy — Dual View Analysis
A2: 2642 Housebills with actual POD | POD_ estimate accuracy at ≥7 Day vs Any Lead Time
A4: VIEW 1: POD_ Published ≥7 Days Before POD | F4: VIEW 2: Latest POD_ (Any Lead Time)
A6: Total HBs | B6: With ≥7d POD_ | C6: POD_ <7d only | D6: No POD_ | F6: Total HBs | G6: With POD_ | H6: Missing POD_ | I6: Median Dev
A7: 2642 | B7: 2520 | C7: 120 | D7: 2 | F7: 2642 | G7: 2570 | H7: 2 | I7: 1.7h
A9: Of the 2520 with ≥7d POD_: | F9: Of the 2570 with any POD_:
A10: Within ±48h | B10: 840 | C10: 33.3% | F10: Within ±48h | G10: 1520 | H10: 59.1%
A11: Late | B11: 1617 | C11: 64.2% | F11: Late | G11: 1003 | H11: 39.0%
A12: Early | B12: 63 | C12: 2.5% | F12: Early | G12: 47 | H12: 1.8%
A14: ≥7d Accuracy (of matched): 840/2520 = 33.3% | F14: Any-lead Accuracy (matched): 1520/2570 = 59.1%
A15: ≥7d Accuracy (overall): 840/2642 = 31.8% | F15: Any-lead Accuracy (overall): 1520/2642 = 57.5%
A16: Median deviation: 209.3h | Mean: 848.8h | F16: Retroactive POD_ (published after POD): 701 HBs excluded
A18: Category | B18: Count | F18: Category | G18: Count
A19: Within ±48h | B19: 840 | F19: Within ±48h | G19: 1520
A20: Late | B20: 1617 | F20: Late | G20: 1003
A21: Early | B21: 63 | F21: Early | G21: 47
A22: POD_ <7d | B22: 120 | F22: Missing POD_ | G22: 2
A23: No POD_ | B23: 2

Sheet Evidence - Reference
A1: REFERENCE COMPLETENESS — Evidence (Updated 16-Feb Meeting)
A3: 16-FEB MEETING KEY DECISIONS:
A4: 1. NO universal DN/CIV format exists — varies by supplier (Bosch internal = 10-digit SAP, externals vary)
A5: 2. Per-supplier, document position IS consistent — basis for AI/OCR approach
A6: 3. Bosch has already done annotation work for OCR — will share with Maersk
A7: 4. Prior German shipment OCR attempt failed (readability <1%) — handwritten, fax, German docs
A8: 5. Chinese supplier docs are standard format — better OCR candidate
A9: 6. Joint AI mini-project to kick off Thursday afternoon
A10: 7. Even 50% automation is a good step forward (Bosch quote)
A11: 8. Maersk to review operational playbook for correct data entry procedures
A12: 9. EDI regex fix needed: IV/INV/iv/Inv variants must all transmit correctly
A15: Current State:
... A22: EDI Regex Fix — Format Variants Found
A23: Current Input | B23: Should Match As | C23: EDI Transmitted? | D23: Fix
A24: IV:ABC123 | B24: Commercial Invoice | C24: Yes | D24: OK
A25: INV:ABC123 | B25: Commercial Invoice | C25: No — format mismatch | D25: Regex fix
A26: inv : ABC123 | B26: Commercial Invoice | C26: No — lowercase + spaces | D26: Regex fix
A27: I N V:ABC123 | B27: Commercial Invoice | C27: No — spaces in prefix | D27: Regex fix
A28: DN N/A | B28: Delivery Note | C28: Yes — but junk value | D28: Validation fix
A29: IV: | B29: Commercial Invoice | C29: Yes — but empty | D29: Validation fix
A30: DN: | B30: Delivery Note | C30: Yes — but empty | D30: Validation fix

Sheet Evidence - Sync & Plausibility
A1: SYNC, DTL & PLAUSIBILITY — Deep Analysis (16-Feb)
A3: THREE-SOURCE SYNC: ROOT CAUSE (from 16-Feb meeting)
A4: CargoWise → Track & Trace Excel: SAME data, full operational extract
A5: CargoWise → Maersk.com: Generic/public subset (standard offering only)
A6: CargoWise → Seeburger DTL → EDI to Bosch: Quality checks FILTER messages
A8: ROOT CAUSE: When DTL checks fail → message blocked → Bosch sees 'missing milestone'
A9: Error log exists internally but no structured feedback loop to operations
A10: PDCA REQUIRED: Document DTL checks, establish ops feedback loop, log monitoring
A13: SC3/SC4 DOUBLE BOOKING (NEW from meeting)
A14: ~1/3 of shipments labeled SC4 were actually received as SC3
A15: Cause: Incomplete SC3 → operator follows up via email → converts to SC4
A16: Bosch suppliers also send emails when SC3 exists → creates duplicates
... A21: MILESTONE INCONSISTENCY — DEEP ANALYSIS (662 Shipments, 1,500 Records)
A22: Metric | B22: Value | C22: Significance
A23: Total records in dataset | B23: 1,500 | C23: Across ETA (1,000) and ATA (500) violations
A24: Unique affected HBLs | B24: 550 of 662 (83%) | C24: Vast majority of flagged shipments have real issues
A25: ETA sequence violations | B25: 475 unique HBLs | C25: Estimates with impossible date order
A26: ATA sequence violations | B26: 76 unique HBLs | C26: ACTUALS recorded in wrong order — data quality failure
A27: Dominant issue | B27: POD > Delivery (83%) | C27: Port arrival dated after door delivery — physically impossible
A28: NON TMC / SC4 share | B28: 63% of ETA violations | C28: Manual entry is the primary root cause (300 HBLs)
A29: 61-90 day gap cluster | B29: 31% of POD>Delivery | C29: Suggests bulk upload / template error pattern
A30: ATA median gap | B30: 73 days | C30: Actuals MORE wrong than estimates — operators entering out-of-sequence
A31: ETA median gap | B31: 15 days | C31: Estimates are wrong but less severely than actuals
A34: DUPLICATION CLARIFICATION:
A35: Multiple ETA rows per HBL = VALID (estimates get revised; 51% of HBLs have 2+ revisions)
A36: ATA rows: duplicated with IDENTICAL dates (multiple containers/TOs per shipment)
A37: No conflicting actual dates found — ATA duplication is structural, not a data quality issue
A38: The 76 ATA violations are genuine sequence errors, not duplication artifacts
A41: POD > DELIVERY GAP SEVERITY (1,010 records — 83% of all violations)
A42: Bucket | B42: ETA Records | C42: ATA Records | D42: % of Total | E42: Likely Cause
A43: 1-7 days | B43: 309 | C43: 52 | D43: 35.7% | E43: Timezone / rounding — low severity but still invalid
A44: 8-30 days | B44: 171 | C44: 28 | D44: 19.7% | E44: Operator error — medium severity
A45: 31-60 days | B45: 99 | C45: 13 | D45: 11.1% | E45: Wrong milestone updated — high severity
A46: 61-90 days | B46: 278 | C46: 32 | D46: 30.7% | E46: Bulk upload / template error — SYSTEMIC pattern
A47: >90 days | B47: 22 | C47: 6 | D47: 2.8% | E47: Data corruption — critical (up to 367 days)
A50: PROPOSED PLAUSIBILITY RULES (for dashboard — committed Nov '25, OVERDUE)
A51: Rule | B51: Condition | C51: Severity | D51: Auto-Action | E51: Expected Catch
A52: Seq: POD > Delivery | B52: Port Discharge after Door Delivery | C52: Critical | D52: Block + alert | E52: 83% of violations
A53: Seq: POL > POD | B53: Vessel departure after port arrival | C53: Critical | D53: Block + alert | E53: 4% of violations
A54: Seq: Pickup > POL | B54: Collection after vessel departure | C54: Critical | D54: Block + alert | E54: 8% of violations
...

Sheet SC4 Trend
A1: SC4 - Week-over-Week Trend Summary
A3: CRITICAL MILESTONES (S00, S02, S04, S07, S31, S45)
A4: Milestone | B4: Type | C4: Metric | D4: Week 1 | E4: Week 2 | F4: Week 3 | G4: Week 4 | H4: W1→W4 Delta
A5: S00 - Shipment created | B5: Actual | C5: Completeness | D5: 0.52 | E5: 0.36 | F5: 0.35 | G5: 0.5 | H5: -0.02
A6: S00 - Shipment created | B6: Actual | C6: Timeliness | D6: 0.52 | E6: 0.36 | F6: 0.35 | G6: 0.49 | H6: -0.03
A7: S02 - Collected | B7: Estimated | C7: Completeness | D7: 0.79 | E7: 0.83 | F7: 0.85 | G7: 0.87 | H7: 0.08
A8: S02 - Collected | B8: Estimated | C8: Timeliness | D8: 0.41 | E8: 0.36 | F8: 0.34 | G8: 0.43 | H8: 0.02
A9: S02 - Collected | B9: Actual | C9: Completeness | D9: 0.92 | E9: 0.95 | F9: 0.88 | G9: 0.9 | H9: -0.02
A10: S02 - Collected | B10: Actual | C10: Timeliness | D10: 0.17 | E10: 0.39 | F10: 0.34 | G10: 0.4 | H10: 0.23
A11: S04 - Vessel/ flight departed | B11: Estimated | C11: Completeness | D11: 0.99 | E11: 0.99 | F11: 0.96 | G11: 0.97 | H11: -0.02
A12: S04 - Vessel/ flight departed | B12: Estimated | C12: Timeliness | D12: 0.38 | E12: 0.43 | F12: 0.37 | G12: 0.43 | H12: 0.05
A13: S04 - Vessel/ flight departed | B13: Actual | C13: Completeness | D13: 0.96 | E13: 0.93 | F13: 0.83 | G13: 0.88 | H13: -0.08
A14: S04 - Vessel/ flight departed | B14: Actual | C14: Timeliness | D14: 0.83 | E14: 0.55 | F14: 0.52 | G14: 0.54 | H14: -0.29
A15: S07 - Vessel/ flight arrived | B15: Estimated | C15: Completeness | D15: 1 | E15: 0.96 | F15: 0.93 | G15: 0.94 | H15: -0.06
A16: S07 - Vessel/ flight arrived | B16: Estimated | C16: Timeliness | D16: 0.26 | E16: 0.21 | F16: 0.18 | G16: 0.22 | H16: -0.04
... A24: S31 - Delivered | B24: Actual | C24: Timeliness | D24: 0.04 | E24: 0.12 | F24: 0.29 | G24: 0.09 | H24: 0.05
A26: Critical Milestone Averages
C27: Avg Completeness | D27: 0.897 | E27: 0.884 | F27: 0.79 | G27: 0.813 | H27: -0.084
C28: Avg Timeliness | D28: 0.474 | E28: 0.482 | F28: 0.424 | G28: 0.416 | H28: -0.058
A31: ALL MILESTONES - AVERAGES
C32: Metric | D32: Week 1 | E32: Week 2 | F32: Week 3 | G32: Week 4 | H32: W1→W4 Delta
C33: Avg Completeness | D33: 0.72238095 | E33: 0.64666667 | F33: 0.61619048 | G33: 0.70809524 | H33: -0.014285714
C34: Avg Timeliness | D34: 0.39238095 | E34: 0.37380952 | F34: 0.33428571 | G34: 0.38714286 | H34: -0.0052380952

Sheet SC3 Trend
A1: SC3 - Week-over-Week Trend Summary
A3: CRITICAL MILESTONES (S02, S04, S07, S31, S45)
A4: Milestone | B4: Type | C4: Metric | D4: Week 1 | E4: Week 2 | F4: Week 3 | G4: Week 4 | H4: W1→W4 Delta
A5: S02 - Collected | B5: Actual | C5: Completeness | D5: 0.813 | E5: 0.792 | F5: 0.73 | G5: 0.791 | H5: -0.022
A6: S02 - Collected | B6: Actual | C6: Timeliness | D6: 0.317 | E6: 0.392 | F6: 0.318 | G6: 0.317 | H6: 0
A7: S02 - Collected | B7: Estimated | C7: Completeness | D7: 0.813 | E7: 0.809 | F7: 0.777 | G7: 0.839 | H7: 0.026
A8: S02 - Collected | B8: Estimated | C8: Timeliness | D8: 0 | E8: 0 | F8: 0 | G8: 0 | H8: 0
A9: S04 - Vessel/ flight departed | B9: Actual | C9: Completeness | D9: 0.866 | E9: 0.864 | F9: 0.843 | G9: 0.801 | H9: -0.065
A10: S04 - Vessel/ flight departed | B10: Actual | C10: Timeliness | D10: 0.858 | E10: 0.858 | F10: 0.817 | G10: 0.781 | H10: -0.077
A11: S04 - Vessel/ flight departed | B11: Estimated | C11: Completeness | D11: 0.866 | E11: 0.895 | F11: 0.863 | G11: 0.846 | H11: -0.02
A12: S04 - Vessel/ flight departed | B12: Estimated | C12: Timeliness | D12: 0.688 | E12: 0.724 | F12: 0.706 | G12: 0.681 | H12: -0.007
A13: S07 - Vessel/ flight arrived | B13: Actual | C13: Completeness | D13: 0.905 | E13: 0.901 | F13: 0.863 | G13: 0.86 | H13: -0.045
A14: S07 - Vessel/ flight arrived | B14: Actual | C14: Timeliness | D14: 0.885 | E14: 0.889 | F14: 0.85 | G14: 0.849 | H14: -0.036
A15: S07 - Vessel/ flight arrived | B15: Estimated | C15: Completeness | D15: 0.881 | E15: 0.913 | F15: 0.879 | G15: 0.866 | H15: -0.015
A16: S07 - Vessel/ flight arrived | B16: Estimated | C16: Timeliness | D16: 0.834 | E16: 0.864 | F16: 0.83 | G16: 0.826 | H16: -0.008
... A24: S31 - Delivered | B24: Estimated | C24: Timeliness | D24: 0.578 | E24: 0.587 | F24: 0.504 | G24: 0.468 | H24: -0.11
A26: Critical Milestone Averages
C27: Avg Completeness | D27: 0.6748 | E27: 0.7042 | F27: 0.697 | G27: 0.7277 | H27: 0.0529
C28: Avg Timeliness | D28: 0.4764 | E28: 0.4997 | F28: 0.4897 | G28: 0.4927 | H28: 0.0163
A31: ALL MILESTONES - AVERAGES
C32: Metric | D32: Week 1 | E32: Week 2 | F32: Week 3 | G32: Week 4 | H32: W1→W4 Delta
C33: Avg Completeness | D33: 0.5738 | E33: 0.6162 | F33: 0.6098 | G33: 0.6302 | H33: 0.0564
C34: Avg Timeliness | D34: 0.4159 | E34: 0.4476 | F34: 0.45055 | G34: 0.4654 | H34: 0.0495

Sheet SC3 vs SC4
A1: SC3 vs SC4 - Critical Milestone Comparison (Week 4 Latest)
C2: SC3 Completeness | E2: SC3 Timeliness | G2: SC4 Completeness | I2: SC4 Timeliness
A3: Milestone | B3: Type | C3: Week 4 | D3: W1→W4 | E3: Week 4 | F3: W1→W4 | G3: Week 4 | H3: W1→W4 | I3: Week 4 | J3: W1→W4
A4: S02 - Collected | B4: Actual | C4: 0.791 | D4: -0.022 | E4: 0.317 | F4: 0 | G4: 0.9 | H4: -0.02 | I4: 0.4 | J4: 0.23
A5: S02 - Collected | B5: Estimated | C5: 0.839 | D5: 0.026 | E5: 0 | F5: 0 | G5: 0.87 | H5: 0.08 | I5: 0.43 | J5: 0.02
A6: S04 - Vessel/ flight departed | B6: Actual | C6: 0.801 | D6: -0.065 | E6: 0.781 | F6: -0.077 | G6: 0.88 | H6: -0.08 | I6: 0.54 | J6: -0.29
A7: S04 - Vessel/ flight departed | B7: Estimated | C7: 0.846 | D7: -0.02 | E7: 0.681 | F7: -0.007 | G7: 0.97 | H7: -0.02 | I7: 0.43 | J7: 0.05
A8: S07 - Vessel/ flight arrived | B8: Actual | C8: 0.86 | D8: -0.045 | E8: 0.849 | F8: -0.036 | G8: 0.84 | H8: 0.01 | I8: 0.52 | J8: 0.19
A9: S07 - Vessel/ flight arrived | B9: Estimated | C9: 0.866 | D9: -0.015 | E9: 0.826 | F9: -0.008 | G9: 0.94 | H9: -0.06 | I9: 0.22 | J9: -0.04
A10: S31 - Delivered | B10: Actual | C10: 0.583 | D10: 0.161 | E10: 0.094 | F10: -0.05 | G10: 0.83 | H10: -0.17 | I10: 0.09 | J10: 0.05
A11: S31 - Delivered | B11: Estimated | C11: 0.709 | D11: -0.013 | E11: 0.468 | F11: -0.11 | G11: 0.98 | H11: 0.02 | I11: 0.67 | J11: -0.13
A12: S45 - Handover to broker | B12: Actual | C12: 0.468 | D12: 0.099 | E12: 0.452 | F12: 0.083 | G12: 0.42 | H12: -0.58 | I12: 0.37 | J12: -0.63
A13: S45 - Handover to broker | B13: Estimated | C13: 0.514 | D13: 0.423 | E13: 0.459 | F13: 0.368 | G13: N/A | H13: N/A | I13: N/A | J13: N/A
A15: SC4 Only - S00 (Shipment Created)
A16: S00 - Shipment created | B16: Actual | C16: N/A | D16: N/A | E16: N/A | F16: N/A | G16: 0.5 | H16: -0.02 | I16: 0.49 | J16: -0.03
