Workbook
Name ___mds_first_cell___: [1]EB!#REF!
Name ___mds_view_data___: #REF!
Name _Mon2: #REF!
Name _Mon3: #REF!
Name _Mon4: #REF!
Name A: #REF!
Name Abteilung: #REF!
Name BEST_2003_NN: '[2]2003_IST'!$F$2:$F$4064
Name BEST_2004_NNN: '[2]2004_IST'!$E$2:$E$10116
Name BLATTA: #REF!
Name Bosch_Material: '[3]8D Form'!$R$17
Name Bosch_product: '[3]8D Form'!$R$16
Name complaint_name: '[3]8D Form'!$F$17
Name Entity: #REF!
Name Feb04_TTNR: [4]TTNR_Checks!$C$2:$C$2454
Name Ges_2003_TTNR: [4]TTNR_Checks!$A$2:$A$4058
Name Gesamtprojekt_Status: #REF!
Name KZ_AUB: [4]TTNR_Checks!$E$2:$E$3002
Name KZ_TTNR_2003: #REF!
Name KZ_TTNR_2004: #REF!
Name laufendes_jahr: #REF!
Name less: [5]Master!$V$36
Name M_1: #REF!
Name M_2: #REF!
Name M_2a: #REF!
Name M_2b: #REF!
Name M_2c: #REF!
Name M_2d: #REF!
Name M_3: #REF!
Name Mon: #REF!
Name more: [5]Master!$V$34
Name partial: [5]Master!$V$35
Name PB: #REF!
Name Period: #REF!
Name Pfad: #REF!
Name PIVOT: #REF!
Name Produktbereich: #REF!
Name Projekt: #REF!
Name qq: #REF!
Name Rechtseinheit: #REF!
Name Reference_No.: '[3]8D Form'!$K$12
Name www: [1]EB!#REF!
Name x_x__MailAutoSig: 'Regional actions'!$F$4

Sheet PDCA Main Page
A1: PDCA Chart 05.02.2026
A2: Problem
B3: Missing milestones & timeliness
A4: Scope
A5: SF
A6: Lane
B7: EUAP | G7: Nov '25 | H7: Dec '25 | I7: Jan '26 | J7: W5 | K7: W6 | L7: W7 | M7: W8 F | N7: W10 F | O7: W12 F | P7: W14 F | Q7: W16 F | R7: W18 F | S7: YTD | T7: W08
A8: Responsible | D8: Completeness (Critical) | G8: 0.82 | H8: 0.84 | I8: 0.84 | J8: ='SC4 Data'!Z27 | K8: ='SC4 Data'!AE27 | L8: ='SC4 Data'!AJ27 | M8: 0.85 | N8: 0.87 | O8: 0.89 | P8: 0.91 | Q8: 0.93 | R8: 0.95 | T8: 0.8527
D9: Timeliness (Critical) | G9: 0.1 | H9: 0.22 | I9: 0.48 | J9: ='SC4 Data'!AA27 | K9: ='SC4 Data'!AF27 | L9: ='SC4 Data'!AK27 | M9: 0.66 | N9: 0.69 | O9: 0.73 | P9: 0.78 | Q9: 0.79 | R9: 0.8 | T9: 0.5402
B10: Maersk MOF execution | D10: Completeness (All) | G10: N/A | H10: N/A | I10: 0.71 | J10: ='SC4 Data'!Z28 | K10: ='SC4 Data'!AE28 | L10: ='SC4 Data'!AJ28 | M10: 0.79 | N10: 0.81 | O10: 0.84 | P10: 0.88 | Q10: 0.91 | R10: 0.95 | T10: 0.7849
D11: Timeliness (All) | G11: N/A | H11: N/A | I11: 0.43 | J11: ='SC4 Data'!AA28 | K11: ='SC4 Data'!AF28 | L11: ='SC4 Data'!AK28 | M11: 0.64 | N11: 0.65 | O11: 0.66 | P11: 0.67 | Q11: 0.68 | R11: 0.7 | T11: 0.4933
D12: ETA accuracy 2P (SC4) | I12: 0.38 | J12: 0.44 | K12: 0.62 | L12: 0.39 | M12: 0.65 | N12: 0.68 | O12: 0.7 | P12: 0.72 | Q12: 0.74 | R12: 0.76 | T12: 0.6667
D13: ETA Accuracy 2D (SC4) | I13: 0.11 | J13: 0.13 | K13: 0.17 | L13: 0.17 | M13: 0.2 | N13: 0.25 | O13: 0.4 | P13: 0.5 | Q13: 0.6 | R13: 0.72 | T13: 0.2876
D14: SC4 Reference Completeness (CIV or DN) | G14: N/A | H14: N/A | I14: 0.69 | J14: 0.71 | K14: 0.74 | L14: 0.76 | M14: 0.78 | N14: 0.82 | O14: 0.84 | P14: 0.86 | Q14: 0.9 | R14: 0.95 | T14: 0.7909
A17: Nr | B17: Main Problems | C17: Product Impact | D17: Category | G17: W01 | H17: W02 | I17: W03 | J17: W04 | K17: W05 | L17: W06 | M17: W07 | N17: W10 | O17: W12 | P17: W14 | Q17: W16 | R17: W18 | S17: YTD
A18: ='Mapping Prob-Root'!A2 | B18: ='Mapping Prob-Root'!O2 | C18: high | D18: Completeness (Critical) | G18: ='SC4 Data'!F5 | H18: ='SC4 Data'!K5 | I18: ='SC4 Data'!P5 | J18: ='SC4 Data'!U5 | K18: ='SC4 Data'!Z5 | L18: ='SC4 Data'!AE5 | M18: ='SC4 Data'!AJ5 | N18: =(AVERAGE(IF((M18-L18)<0,-(M18-L18),(M18-L18)),IF((L18-K18)<0,-(L18-K18),(L18-K18)),IF((K18-J18)<0,-(K18-J18),(K18-J18)))*$T18)+M18 | O18: =(AVERAGE(IF((N18-M18)<0,-(N18-M18),(N18-M18)),IF((M18-L18)<0,-(M18-L18),(M18-L18)),IF((L18-K18)<0,-(L18-K18),(L18-K18)))*$T18)+N18 | P18: =(AVERAGE(IF((O18-N18)<0,-(O18-N18),(O18-N18)),IF((N18-M18)<0,-(N18-M18),(N18-M18)),IF((M18-L18)<0,-(M18-L18),(M18-L18)))*$T18)+O18 | Q18: =(AVERAGE(IF((P18-O18)<0,-(P18-O18),(P18-O18)),IF((O18-N18)<0,-(O18-N18),(O18-N18)),IF((N18-M18)<0,-(N18-M18),(N18-M18)))*$T18)+P18 | R18: =(AVERAGE(IF((Q18-P18)<0,-(Q18-P18),(Q18-P18)),IF((P18-O18)<0,-(P18-O18),(P18-O18)),IF((O18-N18)<0,-(O18-N18),(O18-N18)))*$T18)+Q18 | S18: =AVERAGE(G18:R18) | T18: 0.4
A19: ='Mapping Prob-Root'!A3 | B19: ='Mapping Prob-Root'!O3 | C19: high | D19: Timeliness (Critical) | G19: ='SC4 Data'!G5 | H19: ='SC4 Data'!L5 | I19: ='SC4 Data'!Q5 | J19: ='SC4 Data'!V5 | K19: ='SC4 Data'!AA5 | L19: ='SC4 Data'!AF5 | M19: ='SC4 Data'!AK5 | N19: =(AVERAGE(IF((M19-L19)<0,-(M19-L19),(M19-L19)),IF((L19-K19)<0,-(L19-K19),(L19-K19)),IF((K19-J19)<0,-(K19-J19),(K19-J19)))*$T19)+M19 | O19: =(AVERAGE(IF((N19-M19)<0,-(N19-M19),(N19-M19)),IF((M19-L19)<0,-(M19-L19),(M19-L19)),IF((L19-K19)<0,-(L19-K19),(L19-K19)))*$T19)+N19 | P19: =(AVERAGE(IF((O19-N19)<0,-(O19-N19),(O19-N19)),IF((N19-M19)<0,-(N19-M19),(N19-M19)),IF((M19-L19)<0,-(M19-L19),(M19-L19)))*$T19)+O19 | Q19: =(AVERAGE(IF((P19-O19)<0,-(P19-O19),(P19-O19)),IF((O19-N19)<0,-(O19-N19),(O19-N19)),IF((N19-M19)<0,-(N19-M19),(N19-M19)))*$T19)+P19 | R19: =(AVERAGE(IF((Q19-P19)<0,-(Q19-P19),(Q19-P19)),IF((P19-O19)<0,-(P19-O19),(P19-O19)),IF((O19-N19)<0,-(O19-N19),(O19-N19)))*$T19)+Q19 | S19: =AVERAGE(G19:R19) | T19: 0.2
A20: ='Mapping Prob-Root'!A4 | B20: ='Mapping Prob-Root'!O4 | C20: high | D20: Completeness (Critical) | G20: ='SC4 Data'!F6 | H20: ='SC4 Data'!K6 | I20: ='SC4 Data'!P6 | J20: ='SC4 Data'!U6 | K20: ='SC4 Data'!Z6 | L20: ='SC4 Data'!AE6 | M20: ='SC4 Data'!AJ6 | N20: =(AVERAGE(IF((M20-L20)<0,-(M20-L20),(M20-L20)),IF((L20-K20)<0,-(L20-K20),(L20-K20)),IF((K20-J20)<0,-(K20-J20),(K20-J20)))*$T20)+M20 | O20: =(AVERAGE(IF((N20-M20)<0,-(N20-M20),(N20-M20)),IF((M20-L20)<0,-(M20-L20),(M20-L20)),IF((L20-K20)<0,-(L20-K20),(L20-K20)))*$T20)+N20 | P20: =(AVERAGE(IF((O20-N20)<0,-(O20-N20),(O20-N20)),IF((N20-M20)<0,-(N20-M20),(N20-M20)),IF((M20-L20)<0,-(M20-L20),(M20-L20)))*$T20)+O20 | Q20: =(AVERAGE(IF((P20-O20)<0,-(P20-O20),(P20-O20)),IF((O20-N20)<0,-(O20-N20),(O20-N20)),IF((N20-M20)<0,-(N20-M20),(N20-M20)))*$T20)+P20 | R20: =(AVERAGE(IF((Q20-P20)<0,-(Q20-P20),(Q20-P20)),IF((P20-O20)<0,-(P20-O20),(P20-O20)),IF((O20-N20)<0,-(O20-N20),(O20-N20)))*$T20)+Q20 | S20: =AVERAGE(G20:R20) | T20: 0.8
A21: ='Mapping Prob-Root'!A5 | B21: ='Mapping Prob-Root'!O5 | C21: high | D21: Timeliness (Critical) | G21: ='SC4 Data'!G6 | H21: ='SC4 Data'!L6 | I21: ='SC4 Data'!Q6 | J21: ='SC4 Data'!V6 | K21: ='SC4 Data'!AA6 | L21: ='SC4 Data'!AF6 | M21: ='SC4 Data'!AK6 | N21: =(AVERAGE(IF((M21-L21)<0,-(M21-L21),(M21-L21)),IF((L21-K21)<0,-(L21-K21),(L21-K21)),IF((K21-J21)<0,-(K21-J21),(K21-J21)))*$T21)+M21 | O21: =(AVERAGE(IF((N21-M21)<0,-(N21-M21),(N21-M21)),IF((M21-L21)<0,-(M21-L21),(M21-L21)),IF((L21-K21)<0,-(L21-K21),(L21-K21)))*$T21)+N21 | P21: =(AVERAGE(IF((O21-N21)<0,-(O21-N21),(O21-N21)),IF((N21-M21)<0,-(N21-M21),(N21-M21)),IF((M21-L21)<0,-(M21-L21),(M21-L21)))*$T21)+O21 | Q21: =(AVERAGE(IF((P21-O21)<0,-(P21-O21),(P21-O21)),IF((O21-N21)<0,-(O21-N21),(O21-N21)),IF((N21-M21)<0,-(N21-M21),(N21-M21)))*$T21)+P21 | R21: =(AVERAGE(IF((Q21-P21)<0,-(Q21-P21),(Q21-P21)),IF((P21-O21)<0,-(P21-O21),(P21-O21)),IF((O21-N21)<0,-(O21-N21),(O21-N21)))*$T21)+Q21 | S21: =AVERAGE(G21:R21) | T21: 0.4
A22: ='Mapping Prob-Root'!A6 | B22: ='Mapping Prob-Root'!O6 | C22: high | D22: Completeness (Critical) | G22: ='SC4 Data'!F7 | H22: ='SC4 Data'!K7 | I22: ='SC4 Data'!P7 | J22: ='SC4 Data'!U7 | K22: ='SC4 Data'!Z7 | L22: ='SC4 Data'!AE7 | M22: ='SC4 Data'!AJ7 | N22: =(AVERAGE(IF((M22-L22)<0,-(M22-L22),(M22-L22)),IF((L22-K22)<0,-(L22-K22),(L22-K22)),IF((K22-J22)<0,-(K22-J22),(K22-J22)))*$T22)+M22 | O22: =(AVERAGE(IF((N22-M22)<0,-(N22-M22),(N22-M22)),IF((M22-L22)<0,-(M22-L22),(M22-L22)),IF((L22-K22)<0,-(L22-K22),(L22-K22)))*$T22)+N22 | P22: =(AVERAGE(IF((O22-N22)<0,-(O22-N22),(O22-N22)),IF((N22-M22)<0,-(N22-M22),(N22-M22)),IF((M22-L22)<0,-(M22-L22),(M22-L22)))*$T22)+O22 | Q22: =(AVERAGE(IF((P22-O22)<0,-(P22-O22),(P22-O22)),IF((O22-N22)<0,-(O22-N22),(O22-N22)),IF((N22-M22)<0,-(N22-M22),(N22-M22)))*$T22)+P22 | R22: =(AVERAGE(IF((Q22-P22)<0,-(Q22-P22),(Q22-P22)),IF((P22-O22)<0,-(P22-O22),(P22-O22)),IF((O22-N22)<0,-(O22-N22),(O22-N22)))*$T22)+Q22 | S22: =AVERAGE(G22:R22) | T22: 1.2
A23: ='Mapping Prob-Root'!A7 | B23: ='Mapping Prob-Root'!O7 | C23: high | D23: Timeliness (Critical) | G23: ='SC4 Data'!G7 | H23: ='SC4 Data'!L7 | I23: ='SC4 Data'!Q7 | J23: ='SC4 Data'!V7 | K23: ='SC4 Data'!AA7 | L23: ='SC4 Data'!AF7 | M23: ='SC4 Data'!AK7 | N23: =(AVERAGE(IF((M23-L23)<0,-(M23-L23),(M23-L23)),IF((L23-K23)<0,-(L23-K23),(L23-K23)),IF((K23-J23)<0,-(K23-J23),(K23-J23)))*$T23)+M23 | O23: =(AVERAGE(IF((N23-M23)<0,-(N23-M23),(N23-M23)),IF((M23-L23)<0,-(M23-L23),(M23-L23)),IF((L23-K23)<0,-(L23-K23),(L23-K23)))*$T23)+N23 | P23: =(AVERAGE(IF((O23-N23)<0,-(O23-N23),(O23-N23)),IF((N23-M23)<0,-(N23-M23),(N23-M23)),IF((M23-L23)<0,-(M23-L23),(M23-L23)))*$T23)+O23 | Q23: =(AVERAGE(IF((P23-O23)<0,-(P23-O23),(P23-O23)),IF((O23-N23)<0,-(O23-N23),(O23-N23)),IF((N23-M23)<0,-(N23-M23),(N23-M23)))*$T23)+P23 | R23: =(AVERAGE(IF((Q23-P23)<0,-(Q23-P23),(Q23-P23)),IF((P23-O23)<0,-(P23-O23),(P23-O23)),IF((O23-N23)<0,-(O23-N23),(O23-N23)))*$T23)+Q23 | S23: =AVERAGE(G23:R23) | T23: 1.4
A24: ='Mapping Prob-Root'!A8 | B24: ='Mapping Prob-Root'!O8 | C24: medium | D24: Completeness (All) | G24: ='SC4 Data'!F8 | H24: ='SC4 Data'!K8 | I24: ='SC4 Data'!P8 | J24: ='SC4 Data'!U8 | K24: ='SC4 Data'!Z8 | L24: ='SC4 Data'!AE8 | M24: ='SC4 Data'!AJ8 | N24: =(AVERAGE(IF((M24-L24)<0,-(M24-L24),(M24-L24)),IF((L24-K24)<0,-(L24-K24),(L24-K24)),IF((K24-J24)<0,-(K24-J24),(K24-J24)))*$T24)+M24 | O24: =(AVERAGE(IF((N24-M24)<0,-(N24-M24),(N24-M24)),IF((M24-L24)<0,-(M24-L24),(M24-L24)),IF((L24-K24)<0,-(L24-K24),(L24-K24)))*$T24)+N24 | P24: =(AVERAGE(IF((O24-N24)<0,-(O24-N24),(O24-N24)),IF((N24-M24)<0,-(N24-M24),(N24-M24)),IF((M24-L24)<0,-(M24-L24),(M24-L24)))*$T24)+O24 | Q24: =(AVERAGE(IF((P24-O24)<0,-(P24-O24),(P24-O24)),IF((O24-N24)<0,-(O24-N24),(O24-N24)),IF((N24-M24)<0,-(N24-M24),(N24-M24)))*$T24)+P24 | R24: =(AVERAGE(IF((Q24-P24)<0,-(Q24-P24),(Q24-P24)),IF((P24-O24)<0,-(P24-O24),(P24-O24)),IF((O24-N24)<0,-(O24-N24),(O24-N24)))*$T24)+Q24 | S24: =AVERAGE(G24:R24) | T24: 0.6
A25: ='Mapping Prob-Root'!A9 | B25: ='Mapping Prob-Root'!O9 | C25: medium | D25: Timeliness (All) | G25: ='SC4 Data'!G8 | H25: ='SC4 Data'!L8 | I25: ='SC4 Data'!Q8 | J25: ='SC4 Data'!V8 | K25: ='SC4 Data'!AA8 | L25: ='SC4 Data'!AF8 | M25: ='SC4 Data'!AK8 | N25: =(AVERAGE(IF((M25-L25)<0,-(M25-L25),(M25-L25)),IF((L25-K25)<0,-(L25-K25),(L25-K25)),IF((K25-J25)<0,-(K25-J25),(K25-J25)))*$T25)+M25 | O25: =(AVERAGE(IF((N25-M25)<0,-(N25-M25),(N25-M25)),IF((M25-L25)<0,-(M25-L25),(M25-L25)),IF((L25-K25)<0,-(L25-K25),(L25-K25)))*$T25)+N25 | P25: =(AVERAGE(IF((O25-N25)<0,-(O25-N25),(O25-N25)),IF((N25-M25)<0,-(N25-M25),(N25-M25)),IF((M25-L25)<0,-(M25-L25),(M25-L25)))*$T25)+O25 | Q25: =(AVERAGE(IF((P25-O25)<0,-(P25-O25),(P25-O25)),IF((O25-N25)<0,-(O25-N25),(O25-N25)),IF((N25-M25)<0,-(N25-M25),(N25-M25)))*$T25)+P25 | R25: =(AVERAGE(IF((Q25-P25)<0,-(Q25-P25),(Q25-P25)),IF((P25-O25)<0,-(P25-O25),(P25-O25)),IF((O25-N25)<0,-(O25-N25),(O25-N25)))*$T25)+Q25 | S25: =AVERAGE(G25:R25) | T25: 0.7
A26: ='Mapping Prob-Root'!A10 | B26: ='Mapping Prob-Root'!O10 | C26: medium | D26: Completeness (All) | G26: ='SC4 Data'!F9 | H26: ='SC4 Data'!K9 | I26: ='SC4 Data'!P9 | J26: ='SC4 Data'!U9 | K26: ='SC4 Data'!Z9 | L26: ='SC4 Data'!AE9 | M26: ='SC4 Data'!AJ9 | N26: =(AVERAGE(IF((M26-L26)<0,-(M26-L26),(M26-L26)),IF((L26-K26)<0,-(L26-K26),(L26-K26)),IF((K26-J26)<0,-(K26-J26),(K26-J26)))*$T26)+M26 | O26: =(AVERAGE(IF((N26-M26)<0,-(N26-M26),(N26-M26)),IF((M26-L26)<0,-(M26-L26),(M26-L26)),IF((L26-K26)<0,-(L26-K26),(L26-K26)))*$T26)+N26 | P26: =(AVERAGE(IF((O26-N26)<0,-(O26-N26),(O26-N26)),IF((N26-M26)<0,-(N26-M26),(N26-M26)),IF((M26-L26)<0,-(M26-L26),(M26-L26)))*$T26)+O26 | Q26: =(AVERAGE(IF((P26-O26)<0,-(P26-O26),(P26-O26)),IF((O26-N26)<0,-(O26-N26),(O26-N26)),IF((N26-M26)<0,-(N26-M26),(N26-M26)))*$T26)+P26 | R26: =(AVERAGE(IF((Q26-P26)<0,-(Q26-P26),(Q26-P26)),IF((P26-O26)<0,-(P26-O26),(P26-O26)),IF((O26-N26)<0,-(O26-N26),(O26-N26)))*$T26)+Q26 | S26: =AVERAGE(G26:R26) | T26: 0.5
A27: ='Mapping Prob-Root'!A11 | B27: ='Mapping Prob-Root'!O11 | C27: medium | D27: Timeliness (All) | G27: ='SC4 Data'!G9 | H27: ='SC4 Data'!L9 | I27: ='SC4 Data'!Q9 | J27: ='SC4 Data'!V9 | K27: ='SC4 Data'!AA9 | L27: ='SC4 Data'!AF9 | M27: ='SC4 Data'!AK9 | N27: =(AVERAGE(IF((M27-L27)<0,-(M27-L27),(M27-L27)),IF((L27-K27)<0,-(L27-K27),(L27-K27)),IF((K27-J27)<0,-(K27-J27),(K27-J27)))*$T27)+M27 | O27: =(AVERAGE(IF((N27-M27)<0,-(N27-M27),(N27-M27)),IF((M27-L27)<0,-(M27-L27),(M27-L27)),IF((L27-K27)<0,-(L27-K27),(L27-K27)))*$T27)+N27 | P27: =(AVERAGE(IF((O27-N27)<0,-(O27-N27),(O27-N27)),IF((N27-M27)<0,-(N27-M27),(N27-M27)),IF((M27-L27)<0,-(M27-L27),(M27-L27)))*$T27)+O27 | Q27: =(AVERAGE(IF((P27-O27)<0,-(P27-O27),(P27-O27)),IF((O27-N27)<0,-(O27-N27),(O27-N27)),IF((N27-M27)<0,-(N27-M27),(N27-M27)))*$T27)+P27 | R27: =(AVERAGE(IF((Q27-P27)<0,-(Q27-P27),(Q27-P27)),IF((P27-O27)<0,-(P27-O27),(P27-O27)),IF((O27-N27)<0,-(O27-N27),(O27-N27)))*$T27)+Q27 | S27: =AVERAGE(G27:R27) | T27: 1
A28: ='Mapping Prob-Root'!A12 | B28: ='Mapping Prob-Root'!O12 | C28: medium | D28: Completeness (All) | G28: ='SC4 Data'!F10 | H28: ='SC4 Data'!K10 | I28: ='SC4 Data'!P10 | J28: ='SC4 Data'!U10 | K28: ='SC4 Data'!Z10 | L28: ='SC4 Data'!AE10 | M28: ='SC4 Data'!AJ10 | N28: =(AVERAGE(IF((M28-L28)<0,-(M28-L28),(M28-L28)),IF((L28-K28)<0,-(L28-K28),(L28-K28)),IF((K28-J28)<0,-(K28-J28),(K28-J28)))*$T28)+M28 | O28: =(AVERAGE(IF((N28-M28)<0,-(N28-M28),(N28-M28)),IF((M28-L28)<0,-(M28-L28),(M28-L28)),IF((L28-K28)<0,-(L28-K28),(L28-K28)))*$T28)+N28 | P28: =(AVERAGE(IF((O28-N28)<0,-(O28-N28),(O28-N28)),IF((N28-M28)<0,-(N28-M28),(N28-M28)),IF((M28-L28)<0,-(M28-L28),(M28-L28)))*$T28)+O28 | Q28: =(AVERAGE(IF((P28-O28)<0,-(P28-O28),(P28-O28)),IF((O28-N28)<0,-(O28-N28),(O28-N28)),IF((N28-M28)<0,-(N28-M28),(N28-M28)))*$T28)+P28 | R28: =(AVERAGE(IF((Q28-P28)<0,-(Q28-P28),(Q28-P28)),IF((P28-O28)<0,-(P28-O28),(P28-O28)),IF((O28-N28)<0,-(O28-N28),(O28-N28)))*$T28)+Q28 | S28: =AVERAGE(G28:R28) | T28: 0.4
A29: ='Mapping Prob-Root'!A13 | B29: ='Mapping Prob-Root'!O13 | C29: medium | D29: Timeliness (All) | G29: ='SC4 Data'!G10 | H29: ='SC4 Data'!L10 | I29: ='SC4 Data'!Q10 | J29: ='SC4 Data'!V10 | K29: ='SC4 Data'!AA10 | L29: ='SC4 Data'!AF10 | M29: ='SC4 Data'!AK10 | N29: =(AVERAGE(IF((M29-L29)<0,-(M29-L29),(M29-L29)),IF((L29-K29)<0,-(L29-K29),(L29-K29)),IF((K29-J29)<0,-(K29-J29),(K29-J29)))*$T29)+M29 | O29: =(AVERAGE(IF((N29-M29)<0,-(N29-M29),(N29-M29)),IF((M29-L29)<0,-(M29-L29),(M29-L29)),IF((L29-K29)<0,-(L29-K29),(L29-K29)))*$T29)+N29 | P29: =(AVERAGE(IF((O29-N29)<0,-(O29-N29),(O29-N29)),IF((N29-M29)<0,-(N29-M29),(N29-M29)),IF((M29-L29)<0,-(M29-L29),(M29-L29)))*$T29)+O29 | Q29: =(AVERAGE(IF((P29-O29)<0,-(P29-O29),(P29-O29)),IF((O29-N29)<0,-(O29-N29),(O29-N29)),IF((N29-M29)<0,-(N29-M29),(N29-M29)))*$T29)+P29 | R29: =(AVERAGE(IF((Q29-P29)<0,-(Q29-P29),(Q29-P29)),IF((P29-O29)<0,-(P29-O29),(P29-O29)),IF((O29-N29)<0,-(O29-N29),(O29-N29)))*$T29)+Q29 | S29: =AVERAGE(G29:R29) | T29: 0.8
A30: ='Mapping Prob-Root'!A14 | B30: ='Mapping Prob-Root'!O14 | C30: medium | D30: Completeness (All) | G30: ='SC4 Data'!F11 | H30: ='SC4 Data'!K11 | I30: ='SC4 Data'!P11 | J30: ='SC4 Data'!U11 | K30: ='SC4 Data'!Z11 | L30: ='SC4 Data'!AE11 | M30: ='SC4 Data'!AJ11 | N30: =(AVERAGE(IF((M30-L30)<0,-(M30-L30),(M30-L30)),IF((L30-K30)<0,-(L30-K30),(L30-K30)),IF((K30-J30)<0,-(K30-J30),(K30-J30)))*$T30)+M30 | O30: =(AVERAGE(IF((N30-M30)<0,-(N30-M30),(N30-M30)),IF((M30-L30)<0,-(M30-L30),(M30-L30)),IF((L30-K30)<0,-(L30-K30),(L30-K30)))*$T30)+N30 | P30: =(AVERAGE(IF((O30-N30)<0,-(O30-N30),(O30-N30)),IF((N30-M30)<0,-(N30-M30),(N30-M30)),IF((M30-L30)<0,-(M30-L30),(M30-L30)))*$T30)+O30 | Q30: =(AVERAGE(IF((P30-O30)<0,-(P30-O30),(P30-O30)),IF((O30-N30)<0,-(O30-N30),(O30-N30)),IF((N30-M30)<0,-(N30-M30),(N30-M30)))*$T30)+P30 | R30: =(AVERAGE(IF((Q30-P30)<0,-(Q30-P30),(Q30-P30)),IF((P30-O30)<0,-(P30-O30),(P30-O30)),IF((O30-N30)<0,-(O30-N30),(O30-N30)))*$T30)+Q30 | S30: =AVERAGE(G30:R30) | T30: 0.8
A31: ='Mapping Prob-Root'!A15 | B31: ='Mapping Prob-Root'!O15 | C31: medium | D31: Timeliness (All) | G31: ='SC4 Data'!G11 | H31: ='SC4 Data'!L11 | I31: ='SC4 Data'!Q11 | J31: ='SC4 Data'!V11 | K31: ='SC4 Data'!AA11 | L31: ='SC4 Data'!AF11 | M31: ='SC4 Data'!AK11 | N31: =(AVERAGE(IF((M31-L31)<0,-(M31-L31),(M31-L31)),IF((L31-K31)<0,-(L31-K31),(L31-K31)),IF((K31-J31)<0,-(K31-J31),(K31-J31)))*$T31)+M31 | O31: =(AVERAGE(IF((N31-M31)<0,-(N31-M31),(N31-M31)),IF((M31-L31)<0,-(M31-L31),(M31-L31)),IF((L31-K31)<0,-(L31-K31),(L31-K31)))*$T31)+N31 | P31: =(AVERAGE(IF((O31-N31)<0,-(O31-N31),(O31-N31)),IF((N31-M31)<0,-(N31-M31),(N31-M31)),IF((M31-L31)<0,-(M31-L31),(M31-L31)))*$T31)+O31 | Q31: =(AVERAGE(IF((P31-O31)<0,-(P31-O31),(P31-O31)),IF((O31-N31)<0,-(O31-N31),(O31-N31)),IF((N31-M31)<0,-(N31-M31),(N31-M31)))*$T31)+P31 | R31: =(AVERAGE(IF((Q31-P31)<0,-(Q31-P31),(Q31-P31)),IF((P31-O31)<0,-(P31-O31),(P31-O31)),IF((O31-N31)<0,-(O31-N31),(O31-N31)))*$T31)+Q31 | S31: =AVERAGE(G31:R31) | T31: 1
A32: ='Mapping Prob-Root'!A16 | B32: ='Mapping Prob-Root'!O16 | C32: medium | D32: Completeness (All) | G32: ='SC4 Data'!F12 | H32: ='SC4 Data'!K12 | I32: ='SC4 Data'!P12 | J32: ='SC4 Data'!U12 | K32: ='SC4 Data'!Z12 | L32: ='SC4 Data'!AE12 | M32: ='SC4 Data'!AJ12 | N32: =(AVERAGE(IF((M32-L32)<0,-(M32-L32),(M32-L32)),IF((L32-K32)<0,-(L32-K32),(L32-K32)),IF((K32-J32)<0,-(K32-J32),(K32-J32)))*$T32)+M32 | O32: =(AVERAGE(IF((N32-M32)<0,-(N32-M32),(N32-M32)),IF((M32-L32)<0,-(M32-L32),(M32-L32)),IF((L32-K32)<0,-(L32-K32),(L32-K32)))*$T32)+N32 | P32: =(AVERAGE(IF((O32-N32)<0,-(O32-N32),(O32-N32)),IF((N32-M32)<0,-(N32-M32),(N32-M32)),IF((M32-L32)<0,-(M32-L32),(M32-L32)))*$T32)+O32 | Q32: =(AVERAGE(IF((P32-O32)<0,-(P32-O32),(P32-O32)),IF((O32-N32)<0,-(O32-N32),(O32-N32)),IF((N32-M32)<0,-(N32-M32),(N32-M32)))*$T32)+P32 | R32: =(AVERAGE(IF((Q32-P32)<0,-(Q32-P32),(Q32-P32)),IF((P32-O32)<0,-(P32-O32),(P32-O32)),IF((O32-N32)<0,-(O32-N32),(O32-N32)))*$T32)+Q32 | S32: =AVERAGE(G32:R32) | T32: 1.1
A33: ='Mapping Prob-Root'!A17 | B33: ='Mapping Prob-Root'!O17 | C33: medium | D33: Timeliness (All) | G33: ='SC4 Data'!G12 | H33: ='SC4 Data'!L12 | I33: ='SC4 Data'!Q12 | J33: ='SC4 Data'!V12 | K33: ='SC4 Data'!AA12 | L33: ='SC4 Data'!AF12 | M33: ='SC4 Data'!AK12 | N33: =(AVERAGE(IF((M33-L33)<0,-(M33-L33),(M33-L33)),IF((L33-K33)<0,-(L33-K33),(L33-K33)),IF((K33-J33)<0,-(K33-J33),(K33-J33)))*$T33)+M33 | O33: =(AVERAGE(IF((N33-M33)<0,-(N33-M33),(N33-M33)),IF((M33-L33)<0,-(M33-L33),(M33-L33)),IF((L33-K33)<0,-(L33-K33),(L33-K33)))*$T33)+N33 | P33: =(AVERAGE(IF((O33-N33)<0,-(O33-N33),(O33-N33)),IF((N33-M33)<0,-(N33-M33),(N33-M33)),IF((M33-L33)<0,-(M33-L33),(M33-L33)))*$T33)+O33 | Q33: =(AVERAGE(IF((P33-O33)<0,-(P33-O33),(P33-O33)),IF((O33-N33)<0,-(O33-N33),(O33-N33)),IF((N33-M33)<0,-(N33-M33),(N33-M33)))*$T33)+P33 | R33: =(AVERAGE(IF((Q33-P33)<0,-(Q33-P33),(Q33-P33)),IF((P33-O33)<0,-(P33-O33),(P33-O33)),IF((O33-N33)<0,-(O33-N33),(O33-N33)))*$T33)+Q33 | S33: =AVERAGE(G33:R33) | T33: 1.3
A34: ='Mapping Prob-Root'!A18 | B34: ='Mapping Prob-Root'!O18 | C34: medium | D34: Completeness (All) | G34: ='SC4 Data'!F13 | H34: ='SC4 Data'!K13 | I34: ='SC4 Data'!P13 | J34: ='SC4 Data'!U13 | K34: ='SC4 Data'!Z13 | L34: ='SC4 Data'!AE13 | M34: ='SC4 Data'!AJ13 | N34: =(AVERAGE(IF((M34-L34)<0,-(M34-L34),(M34-L34)),IF((L34-K34)<0,-(L34-K34),(L34-K34)),IF((K34-J34)<0,-(K34-J34),(K34-J34)))*$T34)+M34 | O34: =(AVERAGE(IF((N34-M34)<0,-(N34-M34),(N34-M34)),IF((M34-L34)<0,-(M34-L34),(M34-L34)),IF((L34-K34)<0,-(L34-K34),(L34-K34)))*$T34)+N34 | P34: =(AVERAGE(IF((O34-N34)<0,-(O34-N34),(O34-N34)),IF((N34-M34)<0,-(N34-M34),(N34-M34)),IF((M34-L34)<0,-(M34-L34),(M34-L34)))*$T34)+O34 | Q34: =(AVERAGE(IF((P34-O34)<0,-(P34-O34),(P34-O34)),IF((O34-N34)<0,-(O34-N34),(O34-N34)),IF((N34-M34)<0,-(N34-M34),(N34-M34)))*$T34)+P34 | R34: =(AVERAGE(IF((Q34-P34)<0,-(Q34-P34),(Q34-P34)),IF((P34-O34)<0,-(P34-O34),(P34-O34)),IF((O34-N34)<0,-(O34-N34),(O34-N34)))*$T34)+Q34 | S34: =AVERAGE(G34:R34) | T34: 0.3
A35: ='Mapping Prob-Root'!A19 | B35: ='Mapping Prob-Root'!O19 | C35: medium | D35: Timeliness (All) | G35: ='SC4 Data'!G13 | H35: ='SC4 Data'!L13 | I35: ='SC4 Data'!Q13 | J35: ='SC4 Data'!V13 | K35: ='SC4 Data'!AA13 | L35: ='SC4 Data'!AF13 | M35: ='SC4 Data'!AK13 | N35: =(AVERAGE(IF((M35-L35)<0,-(M35-L35),(M35-L35)),IF((L35-K35)<0,-(L35-K35),(L35-K35)),IF((K35-J35)<0,-(K35-J35),(K35-J35)))*$T35)+M35 | O35: =(AVERAGE(IF((N35-M35)<0,-(N35-M35),(N35-M35)),IF((M35-L35)<0,-(M35-L35),(M35-L35)),IF((L35-K35)<0,-(L35-K35),(L35-K35)))*$T35)+N35 | P35: =(AVERAGE(IF((O35-N35)<0,-(O35-N35),(O35-N35)),IF((N35-M35)<0,-(N35-M35),(N35-M35)),IF((M35-L35)<0,-(M35-L35),(M35-L35)))*$T35)+O35 | Q35: =(AVERAGE(IF((P35-O35)<0,-(P35-O35),(P35-O35)),IF((O35-N35)<0,-(O35-N35),(O35-N35)),IF((N35-M35)<0,-(N35-M35),(N35-M35)))*$T35)+P35 | R35: =(AVERAGE(IF((Q35-P35)<0,-(Q35-P35),(Q35-P35)),IF((P35-O35)<0,-(P35-O35),(P35-O35)),IF((O35-N35)<0,-(O35-N35),(O35-N35)))*$T35)+Q35 | S35: =AVERAGE(G35:R35) | T35: 1
A36: ='Mapping Prob-Root'!A20 | B36: ='Mapping Prob-Root'!O20 | C36: high | D36: Completeness (Critical) | G36: ='SC4 Data'!F14 | H36: ='SC4 Data'!K14 | I36: ='SC4 Data'!P14 | J36: ='SC4 Data'!U14 | K36: ='SC4 Data'!Z14 | L36: ='SC4 Data'!AE14 | M36: ='SC4 Data'!AJ14 | N36: =(AVERAGE(IF((M36-L36)<0,-(M36-L36),(M36-L36)),IF((L36-K36)<0,-(L36-K36),(L36-K36)),IF((K36-J36)<0,-(K36-J36),(K36-J36)))*$T36)+M36 | O36: =(AVERAGE(IF((N36-M36)<0,-(N36-M36),(N36-M36)),IF((M36-L36)<0,-(M36-L36),(M36-L36)),IF((L36-K36)<0,-(L36-K36),(L36-K36)))*$T36)+N36 | P36: =(AVERAGE(IF((O36-N36)<0,-(O36-N36),(O36-N36)),IF((N36-M36)<0,-(N36-M36),(N36-M36)),IF((M36-L36)<0,-(M36-L36),(M36-L36)))*$T36)+O36 | Q36: =(AVERAGE(IF((P36-O36)<0,-(P36-O36),(P36-O36)),IF((O36-N36)<0,-(O36-N36),(O36-N36)),IF((N36-M36)<0,-(N36-M36),(N36-M36)))*$T36)+P36 | R36: =(AVERAGE(IF((Q36-P36)<0,-(Q36-P36),(Q36-P36)),IF((P36-O36)<0,-(P36-O36),(P36-O36)),IF((O36-N36)<0,-(O36-N36),(O36-N36)))*$T36)+Q36 | S36: =AVERAGE(G36:R36) | T36: 0.7
A37: ='Mapping Prob-Root'!A21 | B37: ='Mapping Prob-Root'!O21 | C37: high | D37: Timeliness (Critical) | G37: ='SC4 Data'!G14 | H37: ='SC4 Data'!L14 | I37: ='SC4 Data'!Q14 | J37: ='SC4 Data'!V14 | K37: ='SC4 Data'!AA14 | L37: ='SC4 Data'!AF14 | M37: ='SC4 Data'!AK14 | N37: =(AVERAGE(IF((M37-L37)<0,-(M37-L37),(M37-L37)),IF((L37-K37)<0,-(L37-K37),(L37-K37)),IF((K37-J37)<0,-(K37-J37),(K37-J37)))*$T37)+M37 | O37: =(AVERAGE(IF((N37-M37)<0,-(N37-M37),(N37-M37)),IF((M37-L37)<0,-(M37-L37),(M37-L37)),IF((L37-K37)<0,-(L37-K37),(L37-K37)))*$T37)+N37 | P37: =(AVERAGE(IF((O37-N37)<0,-(O37-N37),(O37-N37)),IF((N37-M37)<0,-(N37-M37),(N37-M37)),IF((M37-L37)<0,-(M37-L37),(M37-L37)))*$T37)+O37 | Q37: =(AVERAGE(IF((P37-O37)<0,-(P37-O37),(P37-O37)),IF((O37-N37)<0,-(O37-N37),(O37-N37)),IF((N37-M37)<0,-(N37-M37),(N37-M37)))*$T37)+P37 | R37: =(AVERAGE(IF((Q37-P37)<0,-(Q37-P37),(Q37-P37)),IF((P37-O37)<0,-(P37-O37),(P37-O37)),IF((O37-N37)<0,-(O37-N37),(O37-N37)))*$T37)+Q37 | S37: =AVERAGE(G37:R37) | T37: 0.2
A38: ='Mapping Prob-Root'!A22 | B38: ='Mapping Prob-Root'!O22 | C38: high | D38: Completeness (Critical) | G38: ='SC4 Data'!F15 | H38: ='SC4 Data'!K15 | I38: ='SC4 Data'!P15 | J38: ='SC4 Data'!U15 | K38: ='SC4 Data'!Z15 | L38: ='SC4 Data'!AE15 | M38: ='SC4 Data'!AJ15 | N38: =(AVERAGE(IF((M38-L38)<0,-(M38-L38),(M38-L38)),IF((L38-K38)<0,-(L38-K38),(L38-K38)),IF((K38-J38)<0,-(K38-J38),(K38-J38)))*$T38)+M38 | O38: =(AVERAGE(IF((N38-M38)<0,-(N38-M38),(N38-M38)),IF((M38-L38)<0,-(M38-L38),(M38-L38)),IF((L38-K38)<0,-(L38-K38),(L38-K38)))*$T38)+N38 | P38: =(AVERAGE(IF((O38-N38)<0,-(O38-N38),(O38-N38)),IF((N38-M38)<0,-(N38-M38),(N38-M38)),IF((M38-L38)<0,-(M38-L38),(M38-L38)))*$T38)+O38 | Q38: =(AVERAGE(IF((P38-O38)<0,-(P38-O38),(P38-O38)),IF((O38-N38)<0,-(O38-N38),(O38-N38)),IF((N38-M38)<0,-(N38-M38),(N38-M38)))*$T38)+P38 | R38: =(AVERAGE(IF((Q38-P38)<0,-(Q38-P38),(Q38-P38)),IF((P38-O38)<0,-(P38-O38),(P38-O38)),IF((O38-N38)<0,-(O38-N38),(O38-N38)))*$T38)+Q38 | S38: =AVERAGE(G38:R38) | T38: 0.4
A39: ='Mapping Prob-Root'!A23 | B39: ='Mapping Prob-Root'!O23 | C39: high | D39: Timeliness (Critical) | G39: ='SC4 Data'!G15 | H39: ='SC4 Data'!L15 | I39: ='SC4 Data'!Q15 | J39: ='SC4 Data'!V15 | K39: ='SC4 Data'!AA15 | L39: ='SC4 Data'!AF15 | M39: ='SC4 Data'!AK15 | N39: =(AVERAGE(IF((M39-L39)<0,-(M39-L39),(M39-L39)),IF((L39-K39)<0,-(L39-K39),(L39-K39)),IF((K39-J39)<0,-(K39-J39),(K39-J39)))*$T39)+M39 | O39: =(AVERAGE(IF((N39-M39)<0,-(N39-M39),(N39-M39)),IF((M39-L39)<0,-(M39-L39),(M39-L39)),IF((L39-K39)<0,-(L39-K39),(L39-K39)))*$T39)+N39 | P39: =(AVERAGE(IF((O39-N39)<0,-(O39-N39),(O39-N39)),IF((N39-M39)<0,-(N39-M39),(N39-M39)),IF((M39-L39)<0,-(M39-L39),(M39-L39)))*$T39)+O39 | Q39: =(AVERAGE(IF((P39-O39)<0,-(P39-O39),(P39-O39)),IF((O39-N39)<0,-(O39-N39),(O39-N39)),IF((N39-M39)<0,-(N39-M39),(N39-M39)))*$T39)+P39 | R39: =(AVERAGE(IF((Q39-P39)<0,-(Q39-P39),(Q39-P39)),IF((P39-O39)<0,-(P39-O39),(P39-O39)),IF((O39-N39)<0,-(O39-N39),(O39-N39)))*$T39)+Q39 | S39: =AVERAGE(G39:R39) | T39: 0.5
A40: ='Mapping Prob-Root'!A24 | B40: ='Mapping Prob-Root'!O24 | C40: high | D40: Completeness (Critical) | G40: ='SC4 Data'!F16 | H40: ='SC4 Data'!K16 | I40: ='SC4 Data'!P16 | J40: ='SC4 Data'!U16 | K40: ='SC4 Data'!Z16 | L40: ='SC4 Data'!AE16 | M40: ='SC4 Data'!AJ16 | N40: =(AVERAGE(IF((M40-L40)<0,-(M40-L40),(M40-L40)),IF((L40-K40)<0,-(L40-K40),(L40-K40)),IF((K40-J40)<0,-(K40-J40),(K40-J40)))*$T40)+M40 | O40: =(AVERAGE(IF((N40-M40)<0,-(N40-M40),(N40-M40)),IF((M40-L40)<0,-(M40-L40),(M40-L40)),IF((L40-K40)<0,-(L40-K40),(L40-K40)))*$T40)+N40 | P40: =(AVERAGE(IF((O40-N40)<0,-(O40-N40),(O40-N40)),IF((N40-M40)<0,-(N40-M40),(N40-M40)),IF((M40-L40)<0,-(M40-L40),(M40-L40)))*$T40)+O40 | Q40: =(AVERAGE(IF((P40-O40)<0,-(P40-O40),(P40-O40)),IF((O40-N40)<0,-(O40-N40),(O40-N40)),IF((N40-M40)<0,-(N40-M40),(N40-M40)))*$T40)+P40 | R40: =(AVERAGE(IF((Q40-P40)<0,-(Q40-P40),(Q40-P40)),IF((P40-O40)<0,-(P40-O40),(P40-O40)),IF((O40-N40)<0,-(O40-N40),(O40-N40)))*$T40)+Q40 | S40: =AVERAGE(G40:R40) | T40: 0.1
A41: ='Mapping Prob-Root'!A25 | B41: ='Mapping Prob-Root'!O25 | C41: high | D41: Timeliness (Critical) | G41: ='SC4 Data'!G16 | H41: ='SC4 Data'!L16 | I41: ='SC4 Data'!Q16 | J41: ='SC4 Data'!V16 | K41: ='SC4 Data'!AA16 | L41: ='SC4 Data'!AF16 | M41: ='SC4 Data'!AK16 | N41: =(AVERAGE(IF((M41-L41)<0,-(M41-L41),(M41-L41)),IF((L41-K41)<0,-(L41-K41),(L41-K41)),IF((K41-J41)<0,-(K41-J41),(K41-J41)))*$T41)+M41 | O41: =(AVERAGE(IF((N41-M41)<0,-(N41-M41),(N41-M41)),IF((M41-L41)<0,-(M41-L41),(M41-L41)),IF((L41-K41)<0,-(L41-K41),(L41-K41)))*$T41)+N41 | P41: =(AVERAGE(IF((O41-N41)<0,-(O41-N41),(O41-N41)),IF((N41-M41)<0,-(N41-M41),(N41-M41)),IF((M41-L41)<0,-(M41-L41),(M41-L41)))*$T41)+O41 | Q41: =(AVERAGE(IF((P41-O41)<0,-(P41-O41),(P41-O41)),IF((O41-N41)<0,-(O41-N41),(O41-N41)),IF((N41-M41)<0,-(N41-M41),(N41-M41)))*$T41)+P41 | R41: =(AVERAGE(IF((Q41-P41)<0,-(Q41-P41),(Q41-P41)),IF((P41-O41)<0,-(P41-O41),(P41-O41)),IF((O41-N41)<0,-(O41-N41),(O41-N41)))*$T41)+Q41 | S41: =AVERAGE(G41:R41) | T41: 1.1
A42: ='Mapping Prob-Root'!A26 | B42: ='Mapping Prob-Root'!O26 | C42: high | D42: Completeness (Critical) | G42: ='SC4 Data'!F17 | H42: ='SC4 Data'!K17 | I42: ='SC4 Data'!P17 | J42: ='SC4 Data'!U17 | K42: ='SC4 Data'!Z17 | L42: ='SC4 Data'!AE17 | M42: ='SC4 Data'!AJ17 | N42: =(AVERAGE(IF((M42-L42)<0,-(M42-L42),(M42-L42)),IF((L42-K42)<0,-(L42-K42),(L42-K42)),IF((K42-J42)<0,-(K42-J42),(K42-J42)))*$T42)+M42 | O42: =(AVERAGE(IF((N42-M42)<0,-(N42-M42),(N42-M42)),IF((M42-L42)<0,-(M42-L42),(M42-L42)),IF((L42-K42)<0,-(L42-K42),(L42-K42)))*$T42)+N42 | P42: =(AVERAGE(IF((O42-N42)<0,-(O42-N42),(O42-N42)),IF((N42-M42)<0,-(N42-M42),(N42-M42)),IF((M42-L42)<0,-(M42-L42),(M42-L42)))*$T42)+O42 | Q42: =(AVERAGE(IF((P42-O42)<0,-(P42-O42),(P42-O42)),IF((O42-N42)<0,-(O42-N42),(O42-N42)),IF((N42-M42)<0,-(N42-M42),(N42-M42)))*$T42)+P42 | R42: =(AVERAGE(IF((Q42-P42)<0,-(Q42-P42),(Q42-P42)),IF((P42-O42)<0,-(P42-O42),(P42-O42)),IF((O42-N42)<0,-(O42-N42),(O42-N42)))*$T42)+Q42 | S42: =AVERAGE(G42:R42) | T42: 0.8
...

Sheet SC4 Data
A1: SC4 - Weekly Milestone Data
A2: Critical Milestones: S00, S02, S04, S07, S31, S45
C3: Week 1 | H3: Week 2 | M3: Week 3 | R3: Week 4 | W3: Week 5 | AB3: Week 6 | AG3: Week 7 | AL3: Week 8
A4: Milestone | B4: Type | C4: Required | D4: Available | E4: In Time | F4: Completeness | G4: Timeliness | H4: Required | I4: Available | J4: In Time | K4: Completeness | L4: Timeliness | M4: Required | N4: Available | O4: In Time | P4: Completeness | Q4: Timeliness | R4: Required | S4: Available | T4: In Time | U4: Completeness | V4: Timeliness | W4: Required | X4: Available | Y4: In Time | Z4: Completeness | AA4: Timeliness | AB4: Required | AC4: Available | AD4: In Time | AE4: Completeness | AF4: Timeliness | AG4: Required | AH4: Available | AI4: In Time | AJ4: Completeness | AK4: Timeliness | AL4: Required | AM4: Available | AN4: In Time | AO4: Completeness | AP4: Timeliness
A5: S00 - Shipment created | B5: Actual | C5: 168 | D5: 88 | E5: 88 | F5: 0.52 | G5: 0.52 | H5: 390 | I5: 141 | J5: 139 | K5: 0.36 | L5: 0.36 | M5: 675 | N5: 236 | O5: 233 | P5: 0.35 | Q5: 0.35 | R5: 719 | S5: 358 | T5: 352 | U5: 0.5 | V5: 0.49 | W5: 527 | X5: 291 | Y5: 288 | Z5: 0.55218216 | AA5: 0.54648956 | AB5: 569 | AC5: 349 | AD5: 341 | AE5: 0.61 | AF5: 0.6 | AG5: 566 | AH5: 436 | AI5: 423 | AJ5: 0.77031802 | AK5: 0.74734982 | AL5: 593 | AM5: 452 | AN5: 424 | AO5: 0.7622 | AP5: 0.715
A6: S02 - Collected | B6: Estimated | C6: 145 | D6: 114 | E6: 59 | F6: 0.79 | G6: 0.41 | H6: 286 | I6: 237 | J6: 104 | K6: 0.83 | L6: 0.36 | M6: 496 | N6: 423 | O6: 167 | P6: 0.85 | Q6: 0.34 | R6: 514 | S6: 447 | T6: 220 | U6: 0.87 | V6: 0.43 | W6: 398 | X6: 337 | Y6: 210 | Z6: 0.84673367 | AA6: 0.52763819 | AB6: 399 | AC6: 359 | AD6: 234 | AE6: 0.9 | AF6: 0.59 | AG6: 446 | AH6: 395 | AI6: 297 | AJ6: 0.88565022 | AK6: 0.66591928 | AL6: 394 | AM6: 349 | AN6: 251 | AO6: 0.8858 | AP6: 0.6371
A7: S02 - Collected | B7: Actual | C7: 145 | D7: 133 | E7: 24 | F7: 0.92 | G7: 0.17 | H7: 286 | I7: 272 | J7: 112 | K7: 0.95 | L7: 0.39 | M7: 496 | N7: 438 | O7: 171 | P7: 0.88 | Q7: 0.34 | R7: 514 | S7: 462 | T7: 207 | U7: 0.9 | V7: 0.4 | W7: 398 | X7: 354 | Y7: 131 | Z7: 0.88944724 | AA7: 0.32914573 | AB7: 399 | AC7: 361 | AD7: 149 | AE7: 0.9 | AF7: 0.37 | AG7: 446 | AH7: 405 | AI7: 171 | AJ7: 0.90807175 | AK7: 0.38340807 | AL7: 394 | AM7: 348 | AN7: 147 | AO7: 0.8832 | AP7: 0.3731
A8: S46 - Documents rcvd from shipper | B8: Actual | C8: 168 | D8: 103 | E8: 45 | F8: 0.61 | G8: 0.27 | H8: 390 | I8: 144 | J8: 72 | K8: 0.37 | L8: 0.18 | M8: 675 | N8: 277 | O8: 104 | P8: 0.41 | Q8: 0.15 | R8: 719 | S8: 435 | T8: 226 | U8: 0.61 | V8: 0.31 | W8: 527 | X8: 357 | Y8: 165 | Z8: 0.67741935 | AA8: 0.31309298 | AB8: 569 | AC8: 418 | AD8: 235 | AE8: 0.73 | AF8: 0.41 | AG8: 566 | AH8: 465 | AI8: 288 | AJ8: 0.82155477 | AK8: 0.50883392 | AL8: 593 | AM8: 488 | AN8: 312 | AO8: 0.8229 | AP8: 0.5261
A9: S10 - On hand at origin SVC | B9: Actual | C9: 154 | D9: 148 | E9: 98 | F9: 0.96 | G9: 0.64 | H9: 335 | I9: 305 | J9: 177 | K9: 0.91 | L9: 0.53 | M9: 535 | N9: 443 | O9: 274 | P9: 0.83 | Q9: 0.51 | R9: 577 | S9: 505 | T9: 281 | U9: 0.88 | V9: 0.49 | W9: 412 | X9: 335 | Y9: 194 | Z9: 0.8131068 | AA9: 0.47087379 | AB9: 461 | AC9: 413 | AD9: 243 | AE9: 0.9 | AF9: 0.53 | AG9: 473 | AH9: 433 | AI9: 268 | AJ9: 0.9154334 | AK9: 0.56659619 | AL9: 463 | AM9: 405 | AN9: 229 | AO9: 0.8747 | AP9: 0.4946
A10: S11 - On hand at origin Hub/ CC | B10: Actual | C10: 154 | D10: 104 | E10: 73 | F10: 0.68 | G10: 0.47 | H10: 335 | I10: 146 | J10: 92 | K10: 0.44 | L10: 0.27 | M10: 535 | N10: 245 | O10: 160 | P10: 0.46 | Q10: 0.3 | R10: 577 | S10: 390 | T10: 205 | U10: 0.68 | V10: 0.36 | W10: 412 | X10: 292 | Y10: 164 | Z10: 0.70873786 | AA10: 0.39805825 | AB10: 461 | AC10: 376 | AD10: 207 | AE10: 0.82 | AF10: 0.45 | AG10: 473 | AH10: 420 | AI10: 252 | AJ10: 0.88794926 | AK10: 0.53276956 | AL10: 463 | AM10: 403 | AN10: 214 | AO10: 0.8704 | AP10: 0.4622
A11: S16 - Shipment booked with carrier | B11: Actual | C11: 168 | D11: 119 | E11: 86 | F11: 0.71 | G11: 0.51 | H11: 390 | I11: 237 | J11: 183 | K11: 0.61 | L11: 0.47 | M11: 675 | N11: 415 | O11: 323 | P11: 0.61 | Q11: 0.48 | R11: 719 | S11: 539 | T11: 439 | U11: 0.75 | V11: 0.61 | W11: 527 | X11: 405 | Y11: 322 | Z11: 0.76850095 | AA11: 0.61100569 | AB11: 569 | AC11: 451 | AD11: 384 | AE11: 0.79 | AF11: 0.67 | AG11: 566 | AH11: 477 | AI11: 381 | AJ11: 0.84275618 | AK11: 0.67314488 | AL11: 593 | AM11: 502 | AN11: 441 | AO11: 0.8465 | AP11: 0.7437
A12: S17 - Tendered carrier | B12: Actual | C12: 154 | D12: 108 | E12: 44 | F12: 0.7 | G12: 0.29 | H12: 335 | I12: 141 | J12: 89 | K12: 0.42 | L12: 0.27 | M12: 535 | N12: 225 | O12: 89 | P12: 0.42 | Q12: 0.17 | R12: 577 | S12: 328 | T12: 172 | U12: 0.57 | V12: 0.3 | W12: 412 | X12: 245 | Y12: 135 | Z12: 0.59466019 | AA12: 0.3276699 | AB12: 461 | AC12: 286 | AD12: 165 | AE12: 0.62 | AF12: 0.36 | AG12: 473 | AH12: 326 | AI12: 129 | AJ12: 0.68921776 | AK12: 0.27272727 | AL12: 463 | AM12: 284 | AN12: 39 | AO12: 0.6134 | AP12: 0.0842
A13: S50 - Received origin CFS | B13: Actual | C13: 115 | D13: 104 | E13: 46 | F13: 0.9 | G13: 0.4 | H13: 190 | I13: 175 | J13: 122 | K13: 0.92 | L13: 0.64 | M13: 354 | N13: 273 | O13: 149 | P13: 0.77 | Q13: 0.42 | R13: 294 | S13: 208 | T13: 96 | U13: 0.71 | V13: 0.33 | W13: 223 | X13: 176 | Y13: 98 | Z13: 0.78923767 | AA13: 0.43946188 | AB13: 183 | AC13: 122 | AD13: 81 | AE13: 0.67 | AF13: 0.44 | AG13: 263 | AH13: 229 | AI13: 76 | AJ13: 0.87072243 | AK13: 0.28897338 | AL13: 259 | AM13: 193 | AN13: 30 | AO13: 0.7452 | AP13: 0.1158
A14: S04 - Vessel/ flight departed | B14: Estimated | C14: 168 | D14: 166 | E14: 63 | F14: 0.99 | G14: 0.38 | H14: 390 | I14: 385 | J14: 166 | K14: 0.99 | L14: 0.43 | M14: 675 | N14: 648 | O14: 248 | P14: 0.96 | Q14: 0.37 | R14: 719 | S14: 696 | T14: 308 | U14: 0.97 | V14: 0.43 | W14: 527 | X14: 504 | Y14: 257 | Z14: 0.95635674 | AA14: 0.48766603 | AB14: 569 | AC14: 551 | AD14: 303 | AE14: 0.97 | AF14: 0.53 | AG14: 566 | AH14: 542 | AI14: 408 | AJ14: 0.95759717 | AK14: 0.72084806 | AL14: 593 | AM14: 554 | AN14: 462 | AO14: 0.9342 | AP14: 0.7791
A15: S04 - Vessel/ flight departed | B15: Actual | C15: 168 | D15: 161 | E15: 140 | F15: 0.96 | G15: 0.83 | H15: 390 | I15: 362 | J15: 213 | K15: 0.93 | L15: 0.55 | M15: 675 | N15: 563 | O15: 353 | P15: 0.83 | Q15: 0.52 | R15: 719 | S15: 630 | T15: 385 | U15: 0.88 | V15: 0.54 | W15: 527 | X15: 471 | Y15: 259 | Z15: 0.89373814 | AA15: 0.4914611 | AB15: 569 | AC15: 500 | AD15: 332 | AE15: 0.88 | AF15: 0.58 | AG15: 566 | AH15: 525 | AI15: 359 | AJ15: 0.92756184 | AK15: 0.63427562 | AL15: 593 | AM15: 528 | AN15: 373 | AO15: 0.8904 | AP15: 0.629
A16: S07 - Vessel/ flight arrived | B16: Estimated | C16: 168 | D16: 168 | E16: 43 | F16: 1 | G16: 0.26 | H16: 390 | I16: 376 | J16: 83 | K16: 0.96 | L16: 0.21 | M16: 675 | N16: 631 | O16: 124 | P16: 0.93 | Q16: 0.18 | R16: 719 | S16: 679 | T16: 159 | U16: 0.94 | V16: 0.22 | W16: 527 | X16: 489 | Y16: 113 | Z16: 0.92789374 | AA16: 0.21442125 | AB16: 569 | AC16: 547 | AD16: 75 | AE16: 0.96 | AF16: 0.13 | AG16: 566 | AH16: 552 | AI16: 139 | AJ16: 0.97526502 | AK16: 0.24558304 | AL16: 593 | AM16: 565 | AN16: 168 | AO16: 0.9528 | AP16: 0.2833
... A25: S31 - Delivered | B25: Actual | C25: 50 | D25: 50 | E25: 2 | F25: 1 | G25: 0.04 | H25: 261 | I25: 261 | J25: 32 | K25: 1 | L25: 0.12 | M25: 462 | N25: 353 | O25: 132 | P25: 0.76 | Q25: 0.29 | R25: 535 | S25: 445 | T25: 48 | U25: 0.83 | V25: 0.09 | W25: 418 | X25: 351 | Y25: 44 | Z25: 0.83971292 | AA25: 0.10526316 | AB25: 459 | AC25: 304 | AD25: 73 | AE25: 0.66 | AF25: 0.16 | AG25: 373 | AH25: 267 | AI25: 49 | AJ25: 0.71581769 | AK25: 0.13136729 | AL25: 475 | AM25: 349 | AN25: 56 | AO25: 0.7347 | AP25: 0.1179
T27: SC3+ SC4 | V27: critical | W27: =SUM(W5:W7,W14:W17,W22,W24:W25,'SC3 Data'!W7:W8,'SC3 Data'!W12:W15,'SC3 Data'!W19:W20,'SC3 Data'!W22:W23) | X27: =SUM(X5:X7,X14:X17,X22,X24:X25,'SC3 Data'!X7:X8,'SC3 Data'!X12:X15,'SC3 Data'!X19:X20,'SC3 Data'!X22:X23) | Y27: =SUM(Y5:Y7,Y14:Y17,Y22,Y24:Y25,'SC3 Data'!Y7:Y8,'SC3 Data'!Y12:Y15,'SC3 Data'!Y19:Y20,'SC3 Data'!Y22:Y23) | Z27: =X27/W27 | AA27: =Y27/X27 | AB27: =SUM(AB5:AB7,AB14:AB17,AB22,AB24:AB25,'SC3 Data'!AB7:AB8,'SC3 Data'!AB12:AB15,'SC3 Data'!AB19:AB20,'SC3 Data'!AB22:AB23) | AC27: =SUM(AC5:AC7,AC14:AC17,AC22,AC24:AC25,'SC3 Data'!AC7:AC8,'SC3 Data'!AC12:AC15,'SC3 Data'!AC19:AC20,'SC3 Data'!AC22:AC23) | AD27: =SUM(AD5:AD7,AD14:AD17,AD22,AD24:AD25,'SC3 Data'!AD7:AD8,'SC3 Data'!AD12:AD15,'SC3 Data'!AD19:AD20,'SC3 Data'!AD22:AD23) | AE27: =AC27/AB27 | AF27: =AD27/AC27 | AG27: =SUM(AG5:AG7,AG14:AG17,AG22,AG24:AG25,'SC3 Data'!AG7:AG8,'SC3 Data'!AG12:AG15,'SC3 Data'!AG19:AG20,'SC3 Data'!AG22:AG23) | AH27: =SUM(AH5:AH7,AH14:AH17,AH22,AH24:AH25,'SC3 Data'!AH7:AH8,'SC3 Data'!AH12:AH15,'SC3 Data'!AH19:AH20,'SC3 Data'!AH22:AH23) | AI27: =SUM(AI5:AI7,AI14:AI17,AI22,AI24:AI25,'SC3 Data'!AI7:AI8,'SC3 Data'!AI12:AI15,'SC3 Data'!AI19:AI20,'SC3 Data'!AI22:AI23) | AJ27: =AH27/AG27 | AK27: =AI27/AH27
V28: all | W28: =SUM(W8:W25,'SC3 Data'!W5:W24) | X28: =SUM(X8:X25,'SC3 Data'!X5:X24) | Y28: =SUM(Y8:Y25,'SC3 Data'!Y5:Y24) | Z28: =X28/W28 | AA28: =Y28/X28 | AB28: =SUM(AB8:AB25,'SC3 Data'!AB5:AB24) | AC28: =SUM(AC8:AC25,'SC3 Data'!AC5:AC24) | AD28: =SUM(AD8:AD25,'SC3 Data'!AD5:AD24) | AE28: =AC28/AB28 | AF28: =AD28/AC28 | AG28: =SUM(AG8:AG25,'SC3 Data'!AG5:AG24) | AH28: =SUM(AH8:AH25,'SC3 Data'!AH5:AH24) | AI28: =SUM(AI8:AI25,'SC3 Data'!AI5:AI24) | AJ28: =AH28/AG28 | AK28: =AI28/AH28

Sheet SC3 Data
A1: SC3 - Weekly Milestone Data
A2: Critical Milestones: S02, S04, S07, S31, S45
C3: Week 1 | H3: Week 2 | M3: Week 3 | R3: Week 4 | W3: Week 5 | AB3: Week 6 | AG3: Week 7 | AL3: Week 8
A4: Milestone | B4: Type | C4: Required | D4: Available | E4: In Time | F4: Completeness | G4: Timeliness | H4: Required | I4: Available | J4: In Time | K4: Completeness | L4: Timeliness | M4: Required | N4: Available | O4: In Time | P4: Completeness | Q4: Timeliness | R4: Required | S4: Available | T4: In Time | U4: Completeness | V4: Timeliness | W4: Required | X4: Available | Y4: In Time | Z4: Completeness | AA4: Timeliness | AB4: Required | AC4: Available | AD4: In Time | AE4: Completeness | AF4: Timeliness | AG4: Required | AH4: Available | AI4: In Time | AJ4: Completeness | AK4: Timeliness | AL4: Required | AM4: Available | AN4: In Time | AO4: Completeness | AP4: Timeliness
A5: S60 - Pre-Booking confirmed | B5: Actual | C5: 29 | D5: 27 | E5: 27 | F5: 0.931 | G5: 0.931 | H5: 36 | I5: 33 | J5: 33 | K5: 0.917 | L5: 0.917 | M5: 51 | N5: 47 | O5: 47 | P5: 0.922 | Q5: 0.922 | R5: 66 | S5: 63 | T5: 62 | U5: 0.955 | V5: 0.939 | W5: 52 | X5: 48 | Y5: 48 | Z5: 0.92307692 | AA5: 0.92307692 | AB5: 76 | AC5: 70 | AD5: 70 | AE5: =AC5/AB5 | AF5: =AD5/AB5 | AG5: 74 | AH5: 69 | AI5: 67 | AJ5: 0.93243243 | AK5: 0.90540541 | AL5: 56 | AM5: 53 | AN5: 52 | AO5: 0.9464 | AP5: 0.9286
A6: S52 - Empty Container picked up | B6: Actual | C6: 26 | D6: 7 | E6: 5 | F6: 0.269 | G6: 0.192 | H6: 27 | I6: 8 | J6: 6 | K6: 0.296 | L6: 0.222 | M6: 47 | N6: 14 | O6: 12 | P6: 0.298 | Q6: 0.255 | R6: 52 | S6: 10 | T6: 6 | U6: 0.192 | V6: 0.115 | W6: 45 | X6: 13 | Y6: 11 | Z6: 0.28888889 | AA6: 0.24444444 | AB6: 46 | AC6: 14 | AD6: 6 | AE6: =AC6/AB6 | AF6: =AD6/AB6 | AG6: 64 | AH6: 22 | AI6: 16 | AJ6: 0.34375 | AK6: 0.25 | AL6: 54 | AM6: 15 | AN6: 4 | AO6: 0.2778 | AP6: 0.0741
A7: S02 - Collected | B7: Actual | C7: 240 | D7: 195 | E7: 76 | F7: 0.813 | G7: 0.317 | H7: 283 | I7: 224 | J7: 111 | K7: 0.792 | L7: 0.392 | M7: 289 | N7: 211 | O7: 92 | P7: 0.73 | Q7: 0.318 | R7: 306 | S7: 242 | T7: 97 | U7: 0.791 | V7: 0.317 | W7: 292 | X7: 221 | Y7: 100 | Z7: 0.75684932 | AA7: 0.34246575 | AB7: 304 | AC7: 239 | AD7: 117 | AE7: =AC7/AB7 | AF7: =AD7/AB7 | AG7: 322 | AH7: 251 | AI7: 131 | AJ7: 0.77950311 | AK7: 0.4068323 | AL7: 302 | AM7: 228 | AN7: 114 | AO7: 0.755 | AP7: 0.3775
A8: S02 - Collected | B8: Estimated | C8: 214 | D8: 174 | E8: 0 | F8: 0.813 | G8: 0 | H8: 256 | I8: 207 | J8: 0 | K8: 0.809 | L8: 0 | M8: 242 | N8: 188 | O8: 0 | P8: 0.777 | Q8: 0 | R8: 254 | S8: 213 | T8: 0 | U8: 0.839 | V8: 0 | W8: 247 | X8: 205 | Y8: 0 | Z8: 0.82995951 | AA8: 0 | AB8: 258 | AC8: 219 | AD8: 0 | AE8: =AC8/AB8 | AF8: =AD8/AB8 | AG8: 258 | AH8: 223 | AI8: 0 | AJ8: 0.86434109 | AK8: 0 | AL8: 248 | AM8: 212 | AN8: 0 | AO8: 0.8548 | AP8: 0
A9: S10 - On hand at origin SVC | B9: Actual | C9: 146 | D9: 138 | E9: 95 | F9: 0.945 | G9: 0.651 | H9: 208 | I9: 194 | J9: 114 | K9: 0.933 | L9: 0.548 | M9: 181 | N9: 162 | O9: 105 | P9: 0.895 | Q9: 0.58 | R9: 198 | S9: 176 | T9: 97 | U9: 0.889 | V9: 0.49 | W9: 183 | X9: 171 | Y9: 108 | Z9: 0.93442623 | AA9: 0.59016393 | AB9: 216 | AC9: 195 | AD9: 104 | AE9: =AC9/AB9 | AF9: =AD9/AB9 | AG9: 213 | AH9: 192 | AI9: 114 | AJ9: 0.90140845 | AK9: 0.53521127 | AL9: 196 | AM9: 180 | AN9: 110 | AO9: 0.9184 | AP9: 0.5612
A10: S50 - Received origin CFS | B10: Actual | C10: 107 | D10: 84 | E10: 75 | F10: 0.785 | G10: 0.701 | H10: 115 | I10: 90 | J10: 82 | K10: 0.783 | L10: 0.713 | M10: 125 | N10: 97 | O10: 84 | P10: 0.776 | Q10: 0.672 | R10: 153 | S10: 106 | T10: 100 | U10: 0.693 | V10: 0.654 | W10: 147 | X10: 117 | Y10: 104 | Z10: 0.79591837 | AA10: 0.70748299 | AB10: 150 | AC10: 96 | AD10: 74 | AE10: =AC10/AB10 | AF10: =AD10/AB10 | AG10: 130 | AH10: 79 | AI10: 55 | AJ10: 0.60769231 | AK10: 0.42307692 | AL10: 123 | AM10: 85 | AN10: 42 | AO10: 0.6911 | AP10: 0.3415
A11: S53 - Full Container loaded on vessel | B11: Actual | C11: 29 | D11: 12 | E11: 11 | F11: 0.414 | G11: 0.379 | H11: 36 | I11: 15 | J11: 14 | K11: 0.417 | L11: 0.389 | M11: 51 | N11: 26 | O11: 25 | P11: 0.51 | Q11: 0.49 | R11: 66 | S11: 28 | T11: 23 | U11: 0.424 | V11: 0.348 | W11: 54 | X11: 37 | Y11: 34 | Z11: 0.68518519 | AA11: 0.62962963 | AB11: 78 | AC11: 46 | AD11: 43 | AE11: =AC11/AB11 | AF11: =AD11/AB11 | AG11: 82 | AH11: 42 | AI11: 30 | AJ11: 0.51219512 | AK11: 0.36585366 | AL11: 66 | AM11: 37 | AN11: 24 | AO11: 0.5606 | AP11: 0.3636
A12: S04 - Vessel/ flight departed | B12: Actual | C12: 253 | D12: 219 | E12: 217 | F12: 0.866 | G12: 0.858 | H12: 323 | I12: 279 | J12: 277 | K12: 0.864 | L12: 0.858 | M12: 306 | N12: 258 | O12: 250 | P12: 0.843 | Q12: 0.817 | R12: 351 | S12: 281 | T12: 274 | U12: 0.801 | V12: 0.781 | W12: 330 | X12: 301 | Y12: 294 | Z12: 0.91212121 | AA12: 0.89090909 | AB12: 366 | AC12: 311 | AD12: 304 | AE12: =AC12/AB12 | AF12: =AD12/AB12 | AG12: 343 | AH12: 283 | AI12: 277 | AJ12: 0.82507289 | AK12: 0.80758017 | AL12: 319 | AM12: 269 | AN12: 263 | AO12: 0.8433 | AP12: 0.8245
A13: S04 - Vessel/ flight departed | B13: Estimated | C13: 253 | D13: 219 | E13: 174 | F13: 0.866 | G13: 0.688 | H13: 323 | I13: 289 | J13: 234 | K13: 0.895 | L13: 0.724 | M13: 306 | N13: 264 | O13: 216 | P13: 0.863 | Q13: 0.706 | R13: 351 | S13: 297 | T13: 239 | U13: 0.846 | V13: 0.681 | W13: 330 | X13: 301 | Y13: 268 | Z13: 0.91212121 | AA13: 0.81212121 | AB13: 366 | AC13: 307 | AD13: 259 | AE13: =AC13/AB13 | AF13: =AD13/AB13 | AG13: 343 | AH13: 288 | AI13: 261 | AJ13: 0.83965015 | AK13: 0.76093294 | AL13: 319 | AM13: 265 | AN13: 231 | AO13: 0.8307 | AP13: 0.7241
A14: S07 - Vessel/ flight arrived | B14: Actual | C14: 253 | D14: 229 | E14: 224 | F14: 0.905 | G14: 0.885 | H14: 323 | I14: 291 | J14: 287 | K14: 0.901 | L14: 0.889 | M14: 306 | N14: 264 | O14: 260 | P14: 0.863 | Q14: 0.85 | R14: 351 | S14: 302 | T14: 298 | U14: 0.86 | V14: 0.849 | W14: 330 | X14: 308 | Y14: 307 | Z14: 0.93333333 | AA14: 0.93030303 | AB14: 366 | AC14: 320 | AD14: 316 | AE14: =AC14/AB14 | AF14: =AD14/AB14 | AG14: 343 | AH14: 303 | AI14: 301 | AJ14: 0.88338192 | AK14: 0.87755102 | AL14: 319 | AM14: 274 | AN14: 273 | AO14: 0.8589 | AP14: 0.8558
A15: S07 - Vessel/ flight arrived | B15: Estimated | C15: 253 | D15: 223 | E15: 211 | F15: 0.881 | G15: 0.834 | H15: 323 | I15: 295 | J15: 279 | K15: 0.913 | L15: 0.864 | M15: 306 | N15: 269 | O15: 254 | P15: 0.879 | Q15: 0.83 | R15: 351 | S15: 304 | T15: 290 | U15: 0.866 | V15: 0.826 | W15: 330 | X15: 309 | Y15: 294 | Z15: 0.93636364 | AA15: 0.89090909 | AB15: 366 | AC15: 325 | AD15: 303 | AE15: =AC15/AB15 | AF15: =AD15/AB15 | AG15: 343 | AH15: 303 | AI15: 272 | AJ15: 0.88338192 | AK15: 0.79300292 | AL15: 319 | AM15: 280 | AN15: 271 | AO15: 0.8777 | AP15: 0.8495
A16: S54 - Full Container discharge from vessel | B16: Actual | C16: 29 | D16: 4 | E16: 2 | F16: 0.138 | G16: 0.069 | H16: 36 | I16: 5 | J16: 5 | K16: 0.139 | L16: 0.139 | M16: 51 | N16: 2 | O16: 0 | P16: 0.039 | Q16: 0 | R16: 66 | S16: 3 | T16: 3 | U16: 0.045 | V16: 0.045 | W16: 54 | X16: 4 | Y16: 3 | Z16: 0.074074074 | AA16: 0.055555556 | AB16: 78 | AC16: 2 | AD16: 2 | AE16: =AC16/AB16 | AF16: =AD16/AB16 | AG16: 82 | AH16: 10 | AI16: 6 | AJ16: 0.12195122 | AK16: 0.073170732 | AL16: 66 | AM16: 12 | AN16: 10 | AO16: 0.1818 | AP16: 0.1515
... A24: S55 - Empty Container returned | B24: Actual | C24: 28 | D24: 10 | E24: 7 | F24: 0.357 | G24: 0.25 | H24: 36 | I24: 24 | J24: 20 | K24: 0.667 | L24: 0.556 | M24: 50 | N24: 31 | O24: 26 | P24: 0.62 | Q24: 0.52 | R24: 64 | S24: 42 | T24: 40 | U24: 0.656 | V24: 0.625 | W24: 52 | X24: 40 | Y24: 40 | Z24: 0.76923077 | AA24: 0.76923077 | AB24: 77 | AC24: 61 | AD24: 60 | AE24: =AC24/AB24 | AF24: =AD24/AB24 | AG24: 80 | AH24: 55 | AI24: 54 | AJ24: 0.6875 | AK24: 0.675 | AL24: 66 | AM24: 49 | AN24: 48 | AO24: 0.7424 | AP24: 0.7273

Sheet Mapping Prob-Root
A1: Nr. | B1: Code | C1: Description | D1: Metric | I1: type | J1: Error | K1: Rootcause | L1: Measure 1 | M1: Measure 2 | N1: Measure 3 | O1: Main problem
A2: 1 | B2: SC4 – S00 | C2: Shipment created (Actual) | D2: Completeness (Critical) | E2: {=_xlfn.TEXTSPLIT(D2,"(")} | F2: Critical) | G2: {=_xlfn.TEXTSPLIT(C2,"(")} | H2: Actual) | I2: =SUBSTITUTE(H2,")","") | J2: =IF(K2="","No RCA","Not received because "&K2) | K2: CW1 configurations are not set up correctly to handle Bosch requirements | L2: =_xlfn.XLOOKUP(K2,Rootcauses!$B$2:$B$21,Rootcauses!$D$2:$D$21) | M2: =_xlfn.XLOOKUP(K2,Rootcauses!$B$2:$B$21,Rootcauses!$E$2:$E$21) | N2: Review the legacy system shipments flow for the branch in Japan | O2: =B2&"- "&I2&" - "&J2
A3: 2 | B3: SC4 – S00 | C3: Shipment created (Actual) | D3: Timeliness (Critical) | E3: {=_xlfn.TEXTSPLIT(D3,"(")} | F3: Critical) | G3: {=_xlfn.TEXTSPLIT(C3,"(")} | H3: Actual) | I3: =SUBSTITUTE(H3,")","") | J3: =IF(K3="","No RCA","Not received because "&K3) | K3: CW1 configurations are not set up correctly to handle Bosch requirements | L3: =_xlfn.XLOOKUP(K3,Rootcauses!$B$2:$B$21,Rootcauses!$D$2:$D$21) | M3: =_xlfn.XLOOKUP(K3,Rootcauses!$B$2:$B$21,Rootcauses!$E$2:$E$21) | N3: Review the legacy system shipments flow for the branch in Japan | O3: =B3&"- "&I3&" - "&J3
A4: 3 | B4: SC4 – S02 | C4: Collected (Estimated) | D4: Completeness (Critical) | E4: {=_xlfn.TEXTSPLIT(D4,"(")} | F4: Critical) | G4: {=_xlfn.TEXTSPLIT(C4,"(")} | H4: Estimated) | I4: =SUBSTITUTE(H4,")","") | J4: =IF(K4="","No RCA","Not received because "&K4) | K4: Manual milestones not updated on time by Operators due to lack of resources | L4: =_xlfn.XLOOKUP(K4,Rootcauses!$B$2:$B$21,Rootcauses!$D$2:$D$21) | M4: =_xlfn.XLOOKUP(K4,Rootcauses!$B$2:$B$21,Rootcauses!$E$2:$E$21) | N4: =_xlfn.XLOOKUP(K4,Rootcauses!$B$2:$B$21,Rootcauses!$F$2:$F$21) | O4: =B4&"- "&I4&" - "&J4
A5: 4 | B5: SC4 – S02 | C5: Collected (Estimated) | D5: Timeliness (Critical) | E5: {=_xlfn.TEXTSPLIT(D5,"(")} | F5: Critical) | G5: {=_xlfn.TEXTSPLIT(C5,"(")} | H5: Estimated) | I5: =SUBSTITUTE(H5,")","") | J5: =IF(K5="","No RCA","Not received because "&K5) | K5: Manual milestones not updated on time by Operators due to lack of resources | L5: =_xlfn.XLOOKUP(K5,Rootcauses!$B$2:$B$21,Rootcauses!$D$2:$D$21) | M5: =_xlfn.XLOOKUP(K5,Rootcauses!$B$2:$B$21,Rootcauses!$E$2:$E$21) | N5: =_xlfn.XLOOKUP(K5,Rootcauses!$B$2:$B$21,Rootcauses!$F$2:$F$21) | O5: =B5&"- "&I5&" - "&J5
A6: 5 | B6: SC4 – S02 | C6: Collected (Actual) | D6: Completeness (Critical) | E6: {=_xlfn.TEXTSPLIT(D6,"(")} | F6: Critical) | G6: {=_xlfn.TEXTSPLIT(C6,"(")} | H6: Actual) | I6: =SUBSTITUTE(H6,")","") | J6: =IF(K6="","No RCA","Not received because "&K6) | K6: Manual milestones not updated on time by Operators due to lack of resources | L6: =_xlfn.XLOOKUP(K6,Rootcauses!$B$2:$B$21,Rootcauses!$D$2:$D$21) | M6: =_xlfn.XLOOKUP(K6,Rootcauses!$B$2:$B$21,Rootcauses!$E$2:$E$21) | N6: =_xlfn.XLOOKUP(K6,Rootcauses!$B$2:$B$21,Rootcauses!$F$2:$F$21) | O6: =B6&"- "&I6&" - "&J6
A7: 6 | B7: SC4 – S02 | C7: Collected (Actual) | D7: Timeliness (Critical) | E7: {=_xlfn.TEXTSPLIT(D7,"(")} | F7: Critical) | G7: {=_xlfn.TEXTSPLIT(C7,"(")} | H7: Actual) | I7: =SUBSTITUTE(H7,")","") | J7: =IF(K7="","No RCA","Not received because "&K7) | K7: Manual milestones not updated on time by Operators due to lack of resources | L7: =_xlfn.XLOOKUP(K7,Rootcauses!$B$2:$B$21,Rootcauses!$D$2:$D$21) | M7: =_xlfn.XLOOKUP(K7,Rootcauses!$B$2:$B$21,Rootcauses!$E$2:$E$21) | N7: =_xlfn.XLOOKUP(K7,Rootcauses!$B$2:$B$21,Rootcauses!$F$2:$F$21) | O7: =B7&"- "&I7&" - "&J7
A8: 7 | B8: SC4 – S46 | C8: Documents rcvd from shipper (Actual) | D8: Completeness (All) | E8: {=_xlfn.TEXTSPLIT(D8,"(")} | F8: All) | G8: {=_xlfn.TEXTSPLIT(C8,"(")} | H8: Actual) | I8: =SUBSTITUTE(H8,")","") | J8: =IF(K8="","No RCA","Not received because "&K8) | K8: SOP to fill CW1 fields are not followed by Operators due to lack of resources | L8: =_xlfn.XLOOKUP(K8,Rootcauses!$B$2:$B$21,Rootcauses!$D$2:$D$21) | M8: =_xlfn.XLOOKUP(K8,Rootcauses!$B$2:$B$21,Rootcauses!$E$2:$E$21) | N8: =_xlfn.XLOOKUP(K8,Rootcauses!$B$2:$B$21,Rootcauses!$F$2:$F$21) | O8: =B8&"- "&I8&" - "&J8
A9: 8 | B9: SC4 – S46 | C9: Documents rcvd from shipper (Actual) | D9: Timeliness (All) | E9: {=_xlfn.TEXTSPLIT(D9,"(")} | F9: All) | G9: {=_xlfn.TEXTSPLIT(C9,"(")} | H9: Actual) | I9: =SUBSTITUTE(H9,")","") | J9: =IF(K9="","No RCA","Not received because "&K9) | K9: SOP to fill CW1 fields are not followed by Operators due to lack of resources | L9: =_xlfn.XLOOKUP(K9,Rootcauses!$B$2:$B$21,Rootcauses!$D$2:$D$21) | M9: =_xlfn.XLOOKUP(K9,Rootcauses!$B$2:$B$21,Rootcauses!$E$2:$E$21) | N9: =_xlfn.XLOOKUP(K9,Rootcauses!$B$2:$B$21,Rootcauses!$F$2:$F$21) | O9: =B9&"- "&I9&" - "&J9
A10: 9 | B10: SC4 – S10 | C10: On hand at origin SVC (Actual) | D10: Completeness (All) | E10: {=_xlfn.TEXTSPLIT(D10,"(")} | F10: All) | G10: {=_xlfn.TEXTSPLIT(C10,"(")} | H10: Actual) | I10: =SUBSTITUTE(H10,")","") | J10: =IF(K10="","No RCA","Not received because "&K10) | K10: Manual milestones not updated on time by Operators due to lack of resources | L10: =_xlfn.XLOOKUP(K10,Rootcauses!$B$2:$B$21,Rootcauses!$D$2:$D$21) | M10: =_xlfn.XLOOKUP(K10,Rootcauses!$B$2:$B$21,Rootcauses!$E$2:$E$21) | N10: =_xlfn.XLOOKUP(K10,Rootcauses!$B$2:$B$21,Rootcauses!$F$2:$F$21) | O10: =B10&"- "&I10&" - "&J10
A11: 10 | B11: SC4 – S10 | C11: On hand at origin SVC (Actual) | D11: Timeliness (All) | E11: {=_xlfn.TEXTSPLIT(D11,"(")} | F11: All) | G11: {=_xlfn.TEXTSPLIT(C11,"(")} | H11: Actual) | I11: =SUBSTITUTE(H11,")","") | J11: =IF(K11="","No RCA","Not received because "&K11) | K11: Manual milestones not updated on time by Operators due to lack of resources | L11: =_xlfn.XLOOKUP(K11,Rootcauses!$B$2:$B$21,Rootcauses!$D$2:$D$21) | M11: =_xlfn.XLOOKUP(K11,Rootcauses!$B$2:$B$21,Rootcauses!$E$2:$E$21) | N11: =_xlfn.XLOOKUP(K11,Rootcauses!$B$2:$B$21,Rootcauses!$F$2:$F$21) | O11: =B11&"- "&I11&" - "&J11
A12: 11 | B12: SC4 – S11 | C12: On hand at origin Hub/CC (Actual) | D12: Completeness (All) | E12: {=_xlfn.TEXTSPLIT(D12,"(")} | F12: All) | G12: {=_xlfn.TEXTSPLIT(C12,"(")} | H12: Actual) | I12: =SUBSTITUTE(H12,")","") | J12: =IF(K12="","No RCA","Not received because "&K12) | L12: =_xlfn.XLOOKUP(K12,Rootcauses!$B$2:$B$21,Rootcauses!$D$2:$D$21) | M12: =_xlfn.XLOOKUP(K12,Rootcauses!$B$2:$B$21,Rootcauses!$E$2:$E$21) | N12: =_xlfn.XLOOKUP(K12,Rootcauses!$B$2:$B$21,Rootcauses!$F$2:$F$21) | O12: =B12&"- "&I12&" - "&J12
A13: 12 | B13: SC4 – S11 | C13: On hand at origin Hub/CC (Actual) | D13: Timeliness (All) | E13: {=_xlfn.TEXTSPLIT(D13,"(")} | F13: All) | G13: {=_xlfn.TEXTSPLIT(C13,"(")} | H13: Actual) | I13: =SUBSTITUTE(H13,")","") | J13: =IF(K13="","No RCA","Not received because "&K13) | K13: Manual milestones not updated on time by Operators due to lack of resources | L13: =_xlfn.XLOOKUP(K13,Rootcauses!$B$2:$B$21,Rootcauses!$D$2:$D$21) | M13: =_xlfn.XLOOKUP(K13,Rootcauses!$B$2:$B$21,Rootcauses!$E$2:$E$21) | N13: =_xlfn.XLOOKUP(K13,Rootcauses!$B$2:$B$21,Rootcauses!$F$2:$F$21) | O13: =B13&"- "&I13&" - "&J13
A14: 13 | B14: SC4 – S16 | C14: Shipment booked with carrier (Actual) | D14: Completeness (All) | E14: {=_xlfn.TEXTSPLIT(D14,"(")} | F14: All) | G14: {=_xlfn.TEXTSPLIT(C14,"(")} | H14: Actual) | I14: =SUBSTITUTE(H14,")","") | J14: =IF(K14="","No RCA","Not received because "&K14) | K14: SOP to fill CW1 fields are not followed by Operators due to lack of resources | L14: =_xlfn.XLOOKUP(K14,Rootcauses!$B$2:$B$21,Rootcauses!$D$2:$D$21) | M14: =_xlfn.XLOOKUP(K14,Rootcauses!$B$2:$B$21,Rootcauses!$E$2:$E$21) | N14: =_xlfn.XLOOKUP(K14,Rootcauses!$B$2:$B$21,Rootcauses!$F$2:$F$21) | O14: =B14&"- "&I14&" - "&J14
A15: 14 | B15: SC4 – S16 | C15: Shipment booked with carrier (Actual) | D15: Timeliness (All) | E15: {=_xlfn.TEXTSPLIT(D15,"(")} | F15: All) | G15: {=_xlfn.TEXTSPLIT(C15,"(")} | H15: Actual) | I15: =SUBSTITUTE(H15,")","") | J15: =IF(K15="","No RCA","Not received because "&K15) | K15: Manual milestones not updated on time by Operators due to lack of resources | L15: =_xlfn.XLOOKUP(K15,Rootcauses!$B$2:$B$21,Rootcauses!$D$2:$D$21) | M15: =_xlfn.XLOOKUP(K15,Rootcauses!$B$2:$B$21,Rootcauses!$E$2:$E$21) | N15: =_xlfn.XLOOKUP(K15,Rootcauses!$B$2:$B$21,Rootcauses!$F$2:$F$21) | O15: =B15&"- "&I15&" - "&J15
A16: 15 | B16: SC4 – S17 | C16: Tendered carrier (Actual) | D16: Completeness (All) | E16: {=_xlfn.TEXTSPLIT(D16,"(")} | F16: All) | G16: {=_xlfn.TEXTSPLIT(C16,"(")} | H16: Actual) | I16: =SUBSTITUTE(H16,")","") | J16: =IF(K16="","No RCA","Not received because "&K16) | K16: CW1 configurations are not set up correctly to handle Bosch requirements | L16: =_xlfn.XLOOKUP(K16,Rootcauses!$B$2:$B$21,Rootcauses!$D$2:$D$21) | M16: =_xlfn.XLOOKUP(K16,Rootcauses!$B$2:$B$21,Rootcauses!$E$2:$E$21) | N16: =_xlfn.XLOOKUP(K16,Rootcauses!$B$2:$B$21,Rootcauses!$F$2:$F$21) | O16: =B16&"- "&I16&" - "&J16
A17: 16 | B17: SC4 – S17 | C17: Tendered carrier (Actual) | D17: Timeliness (All) | E17: {=_xlfn.TEXTSPLIT(D17,"(")} | F17: All) | G17: {=_xlfn.TEXTSPLIT(C17,"(")} | H17: Actual) | I17: =SUBSTITUTE(H17,")","") | J17: =IF(K17="","No RCA","Not received because "&K17) | K17: CW1 configurations are not set up correctly to handle Bosch requirements | L17: =_xlfn.XLOOKUP(K17,Rootcauses!$B$2:$B$21,Rootcauses!$D$2:$D$21) | M17: =_xlfn.XLOOKUP(K17,Rootcauses!$B$2:$B$21,Rootcauses!$E$2:$E$21) | N17: =_xlfn.XLOOKUP(K17,Rootcauses!$B$2:$B$21,Rootcauses!$F$2:$F$21) | O17: =B17&"- "&I17&" - "&J17
A18: 17 | B18: SC4 – S50 | C18: Received origin CFS (Actual) | D18: Completeness (All) | E18: {=_xlfn.TEXTSPLIT(D18,"(")} | F18: All) | G18: {=_xlfn.TEXTSPLIT(C18,"(")} | H18: Actual) | I18: =SUBSTITUTE(H18,")","") | J18: =IF(K18="","No RCA","Not received because "&K18) | K18: SOP to fill CW1 fields are not followed by Operators due to lack of resources | L18: =_xlfn.XLOOKUP(K18,Rootcauses!$B$2:$B$21,Rootcauses!$D$2:$D$21) | M18: =_xlfn.XLOOKUP(K18,Rootcauses!$B$2:$B$21,Rootcauses!$E$2:$E$21) | N18: =_xlfn.XLOOKUP(K18,Rootcauses!$B$2:$B$21,Rootcauses!$F$2:$F$21) | O18: =B18&"- "&I18&" - "&J18
A19: 18 | B19: SC4 – S50 | C19: Received origin CFS (Actual) | D19: Timeliness (All) | E19: {=_xlfn.TEXTSPLIT(D19,"(")} | F19: All) | G19: {=_xlfn.TEXTSPLIT(C19,"(")} | H19: Actual) | I19: =SUBSTITUTE(H19,")","") | J19: =IF(K19="","No RCA","Not received because "&K19) | K19: CW1 configurations are not set up correctly to handle Bosch requirements | L19: =_xlfn.XLOOKUP(K19,Rootcauses!$B$2:$B$21,Rootcauses!$D$2:$D$21) | M19: =_xlfn.XLOOKUP(K19,Rootcauses!$B$2:$B$21,Rootcauses!$E$2:$E$21) | N19: =_xlfn.XLOOKUP(K19,Rootcauses!$B$2:$B$21,Rootcauses!$F$2:$F$21) | O19: =B19&"- "&I19&" - "&J19
A20: 19 | B20: SC4 – S04 | C20: Vessel/flight departed (Estimated) | D20: Completeness (Critical) | E20: {=_xlfn.TEXTSPLIT(D20,"(")} | F20: Critical) | G20: {=_xlfn.TEXTSPLIT(C20,"(")} | H20: Estimated) | I20: =SUBSTITUTE(H20,")","") | J20: =IF(K20="","No RCA","Not received because "&K20) | K20: The Consol is not attached to shipment with "is Linked" Flag | L20: =_xlfn.XLOOKUP(K20,Rootcauses!$B$2:$B$21,Rootcauses!$D$2:$D$21) | M20: =_xlfn.XLOOKUP(K20,Rootcauses!$B$2:$B$21,Rootcauses!$E$2:$E$21) | N20: =_xlfn.XLOOKUP(K20,Rootcauses!$B$2:$B$21,Rootcauses!$F$2:$F$21) | O20: =B20&"- "&I20&" - "&J20
A21: 20 | B21: SC4 – S04 | C21: Vessel/flight departed (Estimated) | D21: Timeliness (Critical) | E21: {=_xlfn.TEXTSPLIT(D21,"(")} | F21: Critical) | G21: {=_xlfn.TEXTSPLIT(C21,"(")} | H21: Estimated) | I21: =SUBSTITUTE(H21,")","") | J21: =IF(K21="","No RCA","Not received because "&K21) | K21: The Consol is not attached to shipment with "is Linked" Flag | L21: =_xlfn.XLOOKUP(K21,Rootcauses!$B$2:$B$21,Rootcauses!$D$2:$D$21) | M21: =_xlfn.XLOOKUP(K21,Rootcauses!$B$2:$B$21,Rootcauses!$E$2:$E$21) | N21: =_xlfn.XLOOKUP(K21,Rootcauses!$B$2:$B$21,Rootcauses!$F$2:$F$21) | O21: =B21&"- "&I21&" - "&J21
A22: 21 | B22: SC4 – S04 | C22: Vessel/flight departed (Actual) | D22: Completeness (Critical) | E22: {=_xlfn.TEXTSPLIT(D22,"(")} | F22: Critical) | G22: {=_xlfn.TEXTSPLIT(C22,"(")} | H22: Actual) | I22: =SUBSTITUTE(H22,")","") | J22: =IF(K22="","No RCA","Not received because "&K22) | K22: The Consol is not attached to shipment with "is Linked" Flag | L22: =_xlfn.XLOOKUP(K22,Rootcauses!$B$2:$B$21,Rootcauses!$D$2:$D$21) | M22: =_xlfn.XLOOKUP(K22,Rootcauses!$B$2:$B$21,Rootcauses!$E$2:$E$21) | N22: =_xlfn.XLOOKUP(K22,Rootcauses!$B$2:$B$21,Rootcauses!$F$2:$F$21) | O22: =B22&"- "&I22&" - "&J22
A23: 22 | B23: SC4 – S04 | C23: Vessel/flight departed (Actual) | D23: Timeliness (Critical) | E23: {=_xlfn.TEXTSPLIT(D23,"(")} | F23: Critical) | G23: {=_xlfn.TEXTSPLIT(C23,"(")} | H23: Actual) | I23: =SUBSTITUTE(H23,")","") | J23: =IF(K23="","No RCA","Not received because "&K23) | K23: The Consol is not attached to shipment with "is Linked" Flag | L23: =_xlfn.XLOOKUP(K23,Rootcauses!$B$2:$B$21,Rootcauses!$D$2:$D$21) | M23: =_xlfn.XLOOKUP(K23,Rootcauses!$B$2:$B$21,Rootcauses!$E$2:$E$21) | N23: =_xlfn.XLOOKUP(K23,Rootcauses!$B$2:$B$21,Rootcauses!$F$2:$F$21) | O23: =B23&"- "&I23&" - "&J23
A24: 23 | B24: SC4 – S07 | C24: Vessel/flight arrived (Estimated) | D24: Completeness (Critical) | E24: {=_xlfn.TEXTSPLIT(D24,"(")} | F24: Critical) | G24: {=_xlfn.TEXTSPLIT(C24,"(")} | H24: Estimated) | I24: =SUBSTITUTE(H24,")","") | J24: =IF(K24="","No RCA","Not received because "&K24) | K24: The Consol is not attached to shipment with "is Linked" Flag | L24: =_xlfn.XLOOKUP(K24,Rootcauses!$B$2:$B$21,Rootcauses!$D$2:$D$21) | M24: =_xlfn.XLOOKUP(K24,Rootcauses!$B$2:$B$21,Rootcauses!$E$2:$E$21) | N24: =_xlfn.XLOOKUP(K24,Rootcauses!$B$2:$B$21,Rootcauses!$F$2:$F$21) | O24: =B24&"- "&I24&" - "&J24
... A43: 42 | B43: SC4 – S31 | C43: Delivered (Actual) | D43: Timeliness (Critical) | E43: {=_xlfn.TEXTSPLIT(D43,"(")} | F43: Critical) | G43: {=_xlfn.TEXTSPLIT(C43,"(")} | H43: Actual) | I43: =SUBSTITUTE(H43,")","") | J43: =IF(K43="","No RCA","Not received because "&K43) | K43: Milestone is dependent on Manual input and is missed due to Lack of resources | L43: =_xlfn.XLOOKUP(K43,Rootcauses!$B$2:$B$21,Rootcauses!$D$2:$D$21) | M43: =_xlfn.XLOOKUP(K43,Rootcauses!$B$2:$B$21,Rootcauses!$E$2:$E$21) | N43: =_xlfn.XLOOKUP(K43,Rootcauses!$B$2:$B$21,Rootcauses!$F$2:$F$21) | O43: =B43&"- "&I43&" - "&J43
A44: 43 | B44: SC3 – S60 | C44: Pre Booking confirmed (Actual) | D44: Completeness (All) | E44: {=_xlfn.TEXTSPLIT(D44,"(")} | F44: All) | G44: {=_xlfn.TEXTSPLIT(C44,"(")} | H44: Actual) | I44: =SUBSTITUTE(H44,")","") | J44: =IF(K44="","No RCA","Not received because "&K44) | L44: =_xlfn.XLOOKUP(K44,Rootcauses!$B$2:$B$21,Rootcauses!$D$2:$D$21) | M44: =_xlfn.XLOOKUP(K44,Rootcauses!$B$2:$B$21,Rootcauses!$E$2:$E$21) | N44: =_xlfn.XLOOKUP(K44,Rootcauses!$B$2:$B$21,Rootcauses!$F$2:$F$21) | O44: =B44&"- "&I44&" - "&J44
